Workbook
Name a: [1]DATABASE!$K$6:$X$163
Name d: [1]DATABASE!$K$6:$X$163
Name HazList: [2]DATABASE!$A$6:$N$163
Name picWAR1: #REF!
Name picWAR1: #REF!
Name picWAR1: #REF!
Name picWAR1: #REF!
Name picWAR1: #REF!
Name picWAR1: #REF!
Name picWAR1: #REF!
Name picWAR1: #REF!
Name picWAR1: #REF!
Name picWAR1: #REF!
Name picWAR1: #REF!
Name picWAR1: #REF!
Name picWAR1: #REF!
Name picWAR1: #REF!
Name picWAR1: #REF!
Name picWAR1: #REF!
Name picWAR1: #REF!
Name picWAR1: #REF!
Name picWAR1: #REF!
Name picWAR1: #REF!
Name picWAR1: #REF!
Name picWAR2: #REF!
Name picWAR2: #REF!
Name picWAR2: #REF!
Name picWAR2: #REF!
Name picWAR2: #REF!
Name picWAR2: #REF!
Name picWAR2: #REF!
Name picWAR2: #REF!
Name picWAR2: #REF!
Name picWAR2: #REF!
Name picWAR2: #REF!
Name picWAR2: #REF!
Name picWAR2: #REF!
Name picWAR2: #REF!
Name picWAR2: #REF!
Name picWAR2: #REF!
Name picWAR2: #REF!
Name picWAR2: #REF!
Name picWAR2: #REF!
Name picWAR2: #REF!
Name picWAR2: #REF!
Name picWAR3: #REF!
Name picWAR3: #REF!
Name picWAR3: #REF!
Name picWAR3: #REF!
Name picWAR3: #REF!
Name picWAR3: #REF!
Name picWAR3: #REF!
Name picWAR3: #REF!
Name picWAR3: #REF!
Name picWAR3: #REF!
Name picWAR3: #REF!
Name picWAR3: #REF!
Name picWAR3: #REF!
Name picWAR3: #REF!
Name picWAR3: #REF!

Sheet 2-5-8-2024
A3: Contract No. | B3: B011 - 2023
A4: Project Title: | B4: Improvement of Road Network
B5: A. Padul Solana - Tuao Road Solana, Cagayan | I5: Municipality: | K5: Tuao
B6: B. Bugnay Tuao to Solana Road Tuao, Cagayan | I6: Week Covered: | K6: February 5-8, 2024
A7: Contractor: | B7: Dragonace Construction Corporation
A9: ACCOMPLISHMENT
A10: Item No. | B10: Description | G10: Location / Station | J10: Quantity for the week | L10: Unit
J11: Physical | K11: Billable
A13: =swa!A43 -> 105(1) | B13: =swa!B43:E43 -> Sub-Grade Preparation(Common Materials) | G13: PCCP | J13: =N18 -> 292.5 | L13: sq.m.
A14: =swa!A45 -> 200(1) | B14: =swa!B45:E45 -> Aggregate Subbase Course | G14: PCCP | J14: =J13*8.1*0.2 -> 473.85 | L14: cu.m.
A15: =swa!A47 -> 311(1)c | B15: =swa!B47:E47 -> Portland Cement Concrete Pavement, 230mm | G15: PCCP | J15: =N18 -> 292.5 | L15: sq.m. | N15: =8*9 -> 72
N16: =65*1.5 -> 97.5 | O16: =102/1.5 -> 68
N17: 3
N18: =N16*3 -> 292.5
A34: FOR VARIATION ORDER
A35: Item No. | B35: Description | G35: Quantity | I35: Unit | J35: Additive | K35: Deductive | L35: New Item
A41: ACTIVITIES FOR THE WEEK: | H41: FIELD INSTRUCTIONS:
A42: Preparation of Sub-grade
A43: Pouring of Concrete for PCCP
A44: Installation of forms for PCCP
A45: Removal of forms for PCCP
A53: PROBLEMS ENCOUNTERED/ REMARKS: | H53: MANPOWER | K53: EQUIPMENT
H54: Description | J54: Quantity | K54: Description | L54: Quantity
H55: Site Engineer | J55: 1 | K55: Transit Mixer | L55: 2
H56: Foreman | J56: 1 | K56: Concrete Vibrator | L56: 2
H57: Skilled Laborer | J57: 4 | K57: Screeder | L57: 1
H58: Laborer | J58: 8 | K58: Loader | L58: 1
A66: WEEKLY PHYSICAL ACCOMPLISHMENT PERCENTAGE (CUMULATIVE):
B68: ORIG. TARGET | D68: REV. TARGET | F68: ACTUAL | H68: VARIANCE | J68: REMARKS
B69: 0.8435 | F69: 0.7055 | H69: =F69-B69 -> -0.138 | J69: On-going
A72: Prepared by: | E72: Checked and Reviewed By: | J72: Conforme:
A74: ALLAN C. BELLO | E74: PORFIRIO S. CANAPI | J74: FERLYN BEA LARON
A75: PEO Engineer I | E75: PEO Engineer II | J75: Contractor's Representative

Sheet 2-12-16-2024
A3: Contract No. | B3: B011 - 2023
A4: Project Title: | B4: Improvement of Road Network
B5: A. Padul Solana - Tuao Road Solana, Cagayan | I5: Municipality: | K5: Tuao
B6: B. Bugnay Tuao to Solana Road Tuao, Cagayan | I6: Week Covered: | K6: February 12-16, 2024
A7: Contractor: | B7: Dragonace Construction Corporation
A9: ACCOMPLISHMENT
A10: Item No. | B10: Description | G10: Location / Station | J10: Quantity for the week | L10: Unit
J11: Physical | K11: Billable
A13: =swa!A43 -> 105(1) | B13: =swa!B43:E43 -> Sub-Grade Preparation(Common Materials) | G13: PCCP | J13: =N18 -> 306 | L13: sq.m.
A14: =swa!A45 -> 200(1) | B14: =swa!B45:E45 -> Aggregate Subbase Course | G14: PCCP | J14: =J13*8.1*0.2 -> 495.72 | L14: cu.m.
A15: =swa!A47 -> 311(1)c | B15: =swa!B47:E47 -> Portland Cement Concrete Pavement, 230mm | G15: PCCP | J15: =N18 -> 306 | L15: sq.m. | N15: =8*9 -> 72
N16: =68*1.5 -> 102 | O16: =102/1.5 -> 68
N17: 3
N18: =N16*3 -> 306
A34: FOR VARIATION ORDER
A35: Item No. | B35: Description | G35: Quantity | I35: Unit | J35: Additive | K35: Deductive | L35: New Item
A41: ACTIVITIES FOR THE WEEK: | H41: FIELD INSTRUCTIONS:
A42: Preparation of Sub-grade
A43: Pouring of Concrete for PCCP
A44: Installation of forms for PCCP
A45: Removal of forms for PCCP
A53: PROBLEMS ENCOUNTERED/ REMARKS: | H53: MANPOWER | K53: EQUIPMENT
H54: Description | J54: Quantity | K54: Description | L54: Quantity
H55: Site Engineer | J55: 1 | K55: Transit Mixer | L55: 2
H56: Foreman | J56: 1 | K56: Concrete Vibrator | L56: 2
H57: Skilled Laborer | J57: 4 | K57: Screeder | L57: 1
H58: Laborer | J58: 8 | K58: Loader | L58: 1
A66: WEEKLY PHYSICAL ACCOMPLISHMENT PERCENTAGE (CUMULATIVE):
B68: ORIG. TARGET | D68: REV. TARGET | F68: ACTUAL | H68: VARIANCE | J68: REMARKS
B69: 0.8562 | F69: 0.7189 | H69: =F69-B69 -> -0.1373 | J69: On-going
A72: Prepared by: | E72: Checked and Reviewed By: | J72: Conforme:
A74: GESIECA D. DUYAO | E74: PORFIRIO S. CANAPI | J74: FERLYN BEA LARON | N74: ='2-5-8-2024'!B69+1.27 -> 2.1135
A75: PEO Engineer I | E75: PEO Engineer II | J75: Contractor's Representative
N78: =84.35+1.27 -> 85.62

Sheet 2-19-23-2024
A3: Contract No. | B3: B011 - 2023
A4: Project Title: | B4: Improvement of Road Network
B5: A. Padul Solana - Tuao Road Solana, Cagayan | I5: Municipality: | K5: Tuao
B6: B. Bugnay Tuao to Solana Road Tuao, Cagayan | I6: Week Covered: | K6: February 19-23 2024
A7: Contractor: | B7: Dragonace Construction Corporation
A9: ACCOMPLISHMENT
A10: Item No. | B10: Description | G10: Location / Station | J10: Quantity for the week | L10: Unit
J11: Physical | K11: Billable
A13: =swa!A43 -> 105(1) | B13: =swa!B43:E43 -> Sub-Grade Preparation(Common Materials) | G13: PCCP | J13: =N18 -> 345 | L13: sq.m.
A14: =swa!A45 -> 200(1) | B14: =swa!B45:E45 -> Aggregate Subbase Course | G14: PCCP | J14: =J13*8.1*0.2 -> 558.9 | L14: cu.m.
A15: =swa!A47 -> 311(1)c | B15: =swa!B47:E47 -> Portland Cement Concrete Pavement, 230mm | G15: PCCP | J15: =N18 -> 345 | L15: sq.m. | N15: =8*9 -> 72
N16: 115 | O16: =102/1.5 -> 68
N17: 3
N18: =N16*3 -> 345
A34: FOR VARIATION ORDER
A35: Item No. | B35: Description | G35: Quantity | I35: Unit | J35: Additive | K35: Deductive | L35: New Item
A41: ACTIVITIES FOR THE WEEK: | H41: FIELD INSTRUCTIONS:
A42: Preparation of Sub-grade
A43: Pouring of Concrete for PCCP
A44: Installation of forms for PCCP
A45: Removal of forms for PCCP
A53: PROBLEMS ENCOUNTERED/ REMARKS: | H53: MANPOWER | K53: EQUIPMENT
H54: Description | J54: Quantity | K54: Description | L54: Quantity
H55: Site Engineer | J55: 1 | K55: Transit Mixer | L55: 2
H56: Foreman | J56: 1 | K56: Concrete Vibrator | L56: 2
H57: Skilled Laborer | J57: 8 | K57: Screeder | L57: 1
H58: Laborer | J58: 16 | K58: Loader | L58: 1
A66: WEEKLY PHYSICAL ACCOMPLISHMENT PERCENTAGE (CUMULATIVE):
B68: ORIG. TARGET | D68: REV. TARGET | F68: ACTUAL | H68: VARIANCE | J68: REMARKS
B69: 0.8696 | F69: 0.7293 | H69: =F69-B69 -> -0.1403 | J69: On-going
A72: Prepared by: | E72: Checked and Reviewed By: | J72: Conforme:
A74: GESIECA D. DUYAO | E74: PORFIRIO S. CANAPI | J74: FERLYN BEA LARON | N74: ='2-5-8-2024'!B69+1.27 -> 2.1135
A75: PEO Engineer I | E75: PEO Engineer II | J75: Contractor's Representative
N78: =84.35+1.27 -> 85.62

Sheet 2-26--3-1-2024
A3: Contract No. | B3: B011 - 2023
A4: Project Title: | B4: Improvement of Road Network
B5: A. Padul Solana - Tuao Road Solana, Cagayan | I5: Municipality: | K5: Tuao
B6: B. Bugnay Tuao to Solana Road Tuao, Cagayan | I6: Week Covered: | K6: February 26 - March 1, 2024
A7: Contractor: | B7: Dragonace Construction Corporation
A9: ACCOMPLISHMENT
A10: Item No. | B10: Description | G10: Location / Station | J10: Quantity for the week | L10: Unit
J11: Physical | K11: Billable
A13: =swa!A43 -> 105(1) | B13: =swa!B43:E43 -> Sub-Grade Preparation(Common Materials) | G13: PCCP | J13: =N18 -> 270 | L13: sq.m.
A14: =swa!A45 -> 200(1) | B14: =swa!B45:E45 -> Aggregate Subbase Course | G14: PCCP | J14: =J13*8.1*0.2 -> 437.4 | L14: cu.m.
A15: =swa!A47 -> 311(1)c | B15: =swa!B47:E47 -> Portland Cement Concrete Pavement, 230mm | G15: PCCP | J15: =N18 -> 270 | L15: sq.m. | N15: =8*9 -> 72
N16: 90 | O16: =102/1.5 -> 68
N17: 3
N18: =N16*3 -> 270
A34: FOR VARIATION ORDER
A35: Item No. | B35: Description | G35: Quantity | I35: Unit | J35: Additive | K35: Deductive | L35: New Item
A41: ACTIVITIES FOR THE WEEK: | H41: FIELD INSTRUCTIONS:
A42: Preparation of Sub-grade
A43: Pouring of Concrete for PCCP
A44: Installation of forms for PCCP
A45: Removal of forms for PCCP
A53: PROBLEMS ENCOUNTERED/ REMARKS: | H53: MANPOWER | K53: EQUIPMENT
H54: Description | J54: Quantity | K54: Description | L54: Quantity
H55: Site Engineer | J55: 1 | K55: Transit Mixer | L55: 2
H56: Foreman | J56: 1 | K56: Concrete Vibrator | L56: 2
H57: Skilled Laborer | J57: 4 | K57: Screeder | L57: 1
H58: Laborer | J58: 8 | K58: Loader | L58: 1
A66: WEEKLY PHYSICAL ACCOMPLISHMENT PERCENTAGE (CUMULATIVE):
B68: ORIG. TARGET | D68: REV. TARGET | F68: ACTUAL | H68: VARIANCE | J68: REMARKS
B69: 0.8899 | F69: 0.7358 | H69: =F69-B69 -> -0.1541 | J69: On-going
A72: Prepared by: | E72: Checked and Reviewed By: | J72: Conforme:
A74: GESIECA D. DUYAO | E74: PORFIRIO S. CANAPI | J74: FERLYN BEA LARON | N74: ='2-5-8-2024'!B69+1.27 -> 2.1135
A75: PEO Engineer I | E75: PEO Engineer II | J75: Contractor's Representative
N78: =84.35+1.27 -> 85.62

Sheet 3-4-8-2024
A3: Contract No. | B3: B011 - 2023
A4: Project Title: | B4: Improvement of Road Network
B5: A. Padul Solana - Tuao Road Solana, Cagayan | I5: Municipality: | K5: Tuao
B6: B. Bugnay Tuao to Solana Road Tuao, Cagayan | I6: Week Covered: | K6: March 4 - 8, 2024
A7: Contractor: | B7: Dragonace Construction Corporation
A9: ACCOMPLISHMENT
A10: Item No. | B10: Description | G10: Location / Station | J10: Quantity for the week | L10: Unit
J11: Physical | K11: Billable
A13: =swa!A43 -> 105(1) | B13: =swa!B43:E43 -> Sub-Grade Preparation(Common Materials) | G13: PCCP | J13: =N18 -> 337.5 | L13: sq.m.
A14: =swa!A45 -> 200(1) | B14: =swa!B45:E45 -> Aggregate Subbase Course | G14: PCCP | J14: =J13*8.1*0.2 -> 546.75 | L14: cu.m.
A15: =swa!A47 -> 311(1)c | B15: =swa!B47:E47 -> Portland Cement Concrete Pavement, 230mm | G15: PCCP | J15: =N18 -> 337.5 | L15: sq.m. | N15: =8*9 -> 72
N16: =75*1.5 -> 112.5 | O16: =102/1.5 -> 68
N17: 3
N18: =N16*3 -> 337.5
A34: FOR VARIATION ORDER
A35: Item No. | B35: Description | G35: Quantity | I35: Unit | J35: Additive | K35: Deductive | L35: New Item
A41: ACTIVITIES FOR THE WEEK: | H41: FIELD INSTRUCTIONS:
A42: Preparation of Sub-grade
A43: Pouring of Concrete for PCCP
A44: Installation of forms for PCCP
A45: Removal of forms for PCCP
A53: PROBLEMS ENCOUNTERED/ REMARKS: | H53: MANPOWER | K53: EQUIPMENT
H54: Description | J54: Quantity | K54: Description | L54: Quantity
H55: Site Engineer | J55: 1 | K55: Transit Mixer | L55: 2
H56: Foreman | J56: 1 | K56: Concrete Vibrator | L56: 2
H57: Skilled Laborer | J57: 8 | K57: Screeder | L57: 1
H58: Laborer | J58: 12 | K58: Loader | L58: 1
A66: WEEKLY PHYSICAL ACCOMPLISHMENT PERCENTAGE (CUMULATIVE):
B68: ORIG. TARGET | D68: REV. TARGET | F68: ACTUAL | H68: VARIANCE | J68: REMARKS
B69: 0.9101 | F69: 0.7432 | H69: =F69-B69 -> -0.1669 | J69: On-going
A72: Prepared by: | E72: Checked and Reviewed By: | J72: Conforme:
A74: GESIECA D. DUYAO | E74: PORFIRIO S. CANAPI | J74: FERLYN BEA LARON | N74: ='2-5-8-2024'!B69+1.27 -> 2.1135
A75: PEO Engineer I | E75: PEO Engineer II | J75: Contractor's Representative
N78: =84.35+1.27 -> 85.62

Sheet 3-18-22-2024
A3: Contract No. | B3: B011 - 2023
A4: Project Title: | B4: Improvement of Road Network
B5: A. Padul Solana - Tuao Road Solana, Cagayan | I5: Municipality: | K5: Tuao
B6: B. Bugnay Tuao to Solana Road Tuao, Cagayan | I6: Week Covered: | K6: March 25-27, 2024
A7: Contractor: | B7: Dragonace Construction Corporation
A9: ACCOMPLISHMENT
A10: Item No. | B10: Description | G10: Location / Station | J10: Quantity for the week | L10: Unit
J11: Physical | K11: Billable
A13: =swa!A43 -> 105(1) | B13: =swa!B43:E43 -> Sub-Grade Preparation(Common Materials) | G13: PCCP | J13: =N18 -> 225 | L13: sq.m.
A14: =swa!A45 -> 200(1) | B14: =swa!B45:E45 -> Aggregate Subbase Course | G14: PCCP | J14: =J13*8.1*0.2 -> 364.5 | L14: cu.m.
A15: =swa!A47 -> 311(1)c | B15: =swa!B47:E47 -> Portland Cement Concrete Pavement, 230mm | G15: PCCP | J15: =N18 -> 225 | L15: sq.m. | N15: =8*9 -> 72
N16: =50*1.5 -> 75 | O16: =102/1.5 -> 68
N17: 3
N18: =N16*3 -> 225
A34: FOR VARIATION ORDER
A35: Item No. | B35: Description | G35: Quantity | I35: Unit | J35: Additive | K35: Deductive | L35: New Item
A41: ACTIVITIES FOR THE WEEK: | H41: FIELD INSTRUCTIONS:
A42: Preparation of Sub-grade
A43: Pouring of Concrete for PCCP
A44: Installation of forms for PCCP
A45: Removal of forms for PCCP
A53: PROBLEMS ENCOUNTERED/ REMARKS: | H53: MANPOWER | K53: EQUIPMENT
H54: Description | J54: Quantity | K54: Description | L54: Quantity
H55: Site Engineer | J55: 1 | K55: Transit Mixer | L55: 2
H56: Foreman | J56: 1 | K56: Concrete Vibrator | L56: 2
H57: Skilled Laborer | J57: 8 | K57: Screeder | L57: 1
H58: Laborer | J58: 12 | K58: Loader | L58: 1
A66: WEEKLY PHYSICAL ACCOMPLISHMENT PERCENTAGE (CUMULATIVE):
B68: ORIG. TARGET | D68: REV. TARGET | F68: ACTUAL | H68: VARIANCE | J68: REMARKS
B69: 0.9607 | F69: 0.8632 | H69: =F69-B69 -> -0.0975 | J69: On-going
A72: Prepared by: | E72: Checked and Reviewed By: | J72: Conforme:
A74: GESIECA D. DUYAO | E74: PORFIRIO S. CANAPI | J74: ROREL S. FERNANDEZ | N74: ='2-5-8-2024'!B69+1.27 -> 2.1135
A75: PEO Engineer I | E75: PEO Engineer II | J75: Contractor's Representative
N78: =84.35+1.27 -> 85.62

Sheet swa
A1: STATEMENT OF WORK ACCOMPLISHED
A3: ='[3]stewa 1-16-31-2023'!B9 -> 45308
A5: Project Name | D5: : | E5: IMPROVEMENT OF ROAD NETWORK
E6: A. PADUL SOLANA TO TUAO ROAD SOLANA, CAGAYAN
E7: B. BUGNAY TUAO TO SOLANA ROAD TUAO, CAGAYAN
A8: Project ID | D8: : | E8: B011-2023 | Q8: accom | R8: accom(inspection)
A9: Location | D9: : | E9: SOLANA-TUAO, CAGAYAN | Q9: 6/14/2023 | R9: 45058
A11: ITEM | B11: DESCRIPTION OF WORK | F11: PROGRAMMED | H11: UNIT | I11: AMOUNT | J11: WEIGHT | K11: ACCOMPLISHMENT | N11: WEIGHT | O11: REMARKS
A12: NO. | F12: QUANTITY | H12: COST | J12: % | K12: PREVIOUS | L12: THIS PERIOD | M12: TO DATE | N12: %
A13: A. | B13: PADUL SOLANA TO TUAO ROAD SOLANA, CAGAYAN
A14: PART A | B14: FACILITIES FOR THE ENGINEERS
A15: A.1.1 (8) | B15: Provision of Field Office for the Engineer (Rental Basis) | F15: month | G15: 6 | H15: 6195 | I15: =ROUND(G15*H15,4) -> 37170 | J15: =I15/$I$68*100 -> 0.070869554 | K15: ='[3]SWA 12-5-2023'!L15 -> 27233.904 | L15: =I15*0.1 -> 3717 | M15: =K15+L15 -> 30950.904 | N15: =M15/$I$68*100 -> 0.059012019 | O15: On-going | Q15: 5 | R15: =G15*U27 -> 4.3961104 | AA15: 55680.66
A16: PART B | B16: OTHER GENERAL REQUIREMENTS | AA16: 2526.58
A17: B.5 | B17: Billboards and Signages | F17: each | G17: 2 | H17: 9912 | I17: =ROUND(G17*H17,4) -> 19824 | J17: =I17/$I$68*100 -> 0.037797095 | K17: ='[3]SWA 12-5-2023'!L17 -> 19824 | M17: =K17+L17 -> 19824 | N17: =M17/$I$68*100 -> 0.037797095 | O17: On-going | Q17: 2 | R17: 2 | AA17: 649545.75
A18: B.7 | B18: Construction Safety and Health Program | F18: l.s. | G18: all | H18: 8053.5 | I18: =ROUND(1*H18,4) -> 8053.5 | J18: =I18/$I$68*100 -> 0.01535507 | K18: ='[3]SWA 12-5-2023'!L18 -> 5900.6792 | L18: =I18*0.1 -> 805.35 | M18: =K18+L18 -> 6706.0292 | N18: =M18/$I$68*100 -> 0.012785938 | O18: On-going | Q18: 0.3 | R18: =U27 -> 0.73268507 | AA18: 620057.55
A19: B.9 | B19: Mobilization/Demobilization | F19: l.s. | G19: all | H19: 204435 | I19: =ROUND(1*H19,4) -> 204435 | J19: =I19/$I$68*100 -> 0.38978255 | K19: ='[3]SWA 12-5-2023'!L19 -> 102217.5 | M19: =K19+L19 -> 102217.5 | N19: =M19/$I$68*100 -> 0.19489127 | O19: On-going | Q19: 0.5 | R19: 0.5 | AA19: 7610185.8
A20: PART C | B20: EARTHWORKS | AA20: 36532287
A21: 102(2) | B21: Roadway Excavation (Surplus Common Excavation- Suitable Materials) | F21: cu.m. | G21: 1057.98 | H21: 246.85 | I21: =ROUND(G21*H21,4) -> 261162.36 | J21: =I21/$I$68*100 -> 0.49794082 | K21: ='[3]SWA 12-5-2023'!L21 -> 221988.01 | M21: =K21+L21 -> 221988.01 | N21: =M21/$I$68*100 -> 0.42324969 | O21: On-going | Q21: 555 | R21: =G21*0.85 -> 899.283 | AA21: 45173.94
A22: 104(1) | B22: Embankment | F22: cu.m. | G22: 5971.01 | H22: 332.88 | I22: =ROUND(G22*H22,4) -> 1987629.8 | J22: =I22/$I$68*100 -> 3.7896809 | K22: ='[3]SWA 12-5-2023'!L22 -> 1689485.3 | M22: =K22+L22 -> 1689485.3 | N22: =M22/$I$68*100 -> 3.2212287 | O22: On-going | Q22: 1500 | R22: =G22*0.85 -> 5075.3585 | AA22: 49961.44
A23: 105(1) | B23: Sub-Grade Preparation(Common Materials) | F23: sq.m. | G23: 20444.4 | H23: 18.64 | I23: =ROUND(G23*H23,4) -> 381083.62 | J23: =I23/$I$68*100 -> 0.72658665 | K23: ='[3]SWA 12-5-2023'!L23 -> 0 | M23: =K23+L23 -> 0 | N23: =M23/$I$68*100 -> 0 | O23: Not Yet Started | Q23: =150*4.5*8.1 -> 5467.5 | AA23: 50224.1
A24: PART D | B24: SUBBASE COURSE | I24: =ROUND(G24*H24,4) -> 0 | K24: ='[3]SWA 12-5-2023'!L24 -> 0 | Q24: 0
A25: 200(1) | B25: Aggregate Subbase Course | F25: cu.m. | G25: 6057.6 | H25: 584.03 | I25: =ROUND(G25*H25,4) -> 3537820.1 | J25: =I25/$I$68*100 -> 6.7453251 | K25: ='[3]SWA 12-5-2023'!L25 -> 0 | M25: =K25+L25 -> 0 | N25: =M25/$I$68*100 -> 0 | O25: Not Yet Started | Q25: =Q23*0.2 -> 1093.5 | AA25: =SUM(AA15:AA23) -> 45615643
A26: PART E | B26: SURFACE COURSE | I26: =ROUND(G26*H26,4) -> 0 | K26: ='[3]SWA 12-5-2023'!L26 -> 0 | Q26: 0
A27: 311(1)C | B27: Portland Cement Concrete Pavement, 230mm | F27: sq.m. | G27: 15396.4 | H27: 1204.01 | I27: =ROUND(G27*H27,4) -> 18537420 | J27: =I27/$I$68*100 -> 35.344059 | K27: ='[3]SWA 12-5-2023'!L27 -> 0 | M27: =K27+L27 -> 0 | N27: =M27/$I$68*100 -> 0 | O27: Not Yet Started | P27: =SUM(I15:I27) -> 24974598 | Q27: =150*4.5*3.05 -> 2058.75 | U27: =R47/G47 -> 0.73268507 | AA27: 50224.1
A28: S U B - T O T A L ( A ) | K28: =SUM(K13:K27) -> 2066649.4 | L28: =SUM(L13:L27) -> 4522.35 | M28: =SUM(M13:M27) -> 2071171.8 | N28: =SUM(N13:N27) -> 3.9489648
A29: B. | B29: BUGNAY TUAO TO SOLANA ROAD TUAO, CAGAYAN
A30: PART A | B30: FACILITIES FOR THE ENGINEERS | Q30: 0 | AA30: =SUM(AA16:AA27) -> 91225830
A31: A.1.1 (8) | B31: Provision of Field Office for the Engineer (Rental Basis) | F31: month | G31: 5.5 | H31: 6195 | I31: =ROUND(G31*H31,4) -> 34072.5 | J31: =I31/$I$68*100 -> 0.064963758 | K31: ='[3]SWA 12-5-2023'!L31 -> 24964.412 | L31: =I31*(0.1+0.2) -> 10221.75 | M31: =K31+L31 -> 35186.162 | N31: =M31/$I$68*100 -> 0.067087103 | O31: On-going | R31: =G31*U27 -> 4.0297679 | U31: =G15+G31 -> 11.5 | AA31: 50224.1
A32: PART B | B32: OTHER GENERAL REQUIREMENTS | U32: =U31*30 -> 345
A33: B.5 | B33: Billboards and Signages | F33: each | G33: 2 | H33: 9912 | I33: =ROUND(G33*H33,4) -> 19824 | J33: =I33/$I$68*100 -> 0.037797095 | K33: ='[3]SWA 12-5-2023'!L33 -> 19824 | M33: =K33+L33 -> 19824 | N33: =M33/$I$68*100 -> 0.037797095 | O33: On-going | R33: 2
A34: B.7 | B34: Construction Safety and Health Program | F34: l.s. | G34: all | H34: 23541 | I34: =ROUND(1*H34,4) -> 23541 | J34: =I34/$I$68*100 -> 0.044884051 | K34: ='[3]SWA 12-5-2023'!L34 -> 17248.139 | M34: =K34+L34 -> 17248.139 | N34: =M34/$I$68*100 -> 0.032885874 | O34: On-going | R34: =U27 -> 0.73268507
A35: B.9 | B35: Mobilization/Demobilization | F35: l.s. | G35: all | H35: 251517 | I35: =ROUND(1*H35,4) -> 251517 | J35: =I35/$I$68*100 -> 0.47955065 | K35: ='[3]SWA 12-5-2023'!L35 -> 125758.5 | M35: =K35+L35 -> 125758.5 | N35: =M35/$I$68*100 -> 0.23977532 | O35: On-going | R35: 0.5
A36: PART C | B36: EARTHWORKS
A37: 101(4)a1 | B37: Removal of Actual Structures/Obstruction (610mmø RCPC) | F37: ln.m. | G37: 30 | H37: 556.52 | I37: =ROUND(G37*H37,4) -> 16695.6 | J37: =I37/$I$68*100 -> 0.031832384 | K37: ='[3]SWA 12-5-2023'!L37 -> 5565.2 | M37: =K37+L37 -> 5565.2 | N37: =M37/$I$68*100 -> 0.010610795 | O37: On-going | R37: 10
A38: 101(4)a3 | B38: Removal of Actual Structures/Obstruction (910mmø RCPC) | F38: ln.m. | G38: 16 | H38: 521.74 | I38: =ROUND(G38*H38,4) -> 8347.84 | J38: =I38/$I$68*100 -> 0.015916268 | K38: ='[3]SWA 12-5-2023'!L38 -> 8347.84 | M38: =K38+L38 -> 8347.84 | N38: =M38/$I$68*100 -> 0.015916268 | O38: On-going | R38: 16
A39: 102(2) | B39: Roadway Excavation (Surplus Common Excavation- Suitable Materials) | F39: cu.m. | G39: 2269.29 | H39: 245.87 | I39: =ROUND(G39*H39,4) -> 557950.33 | J39: =I39/$I$68*100 -> 1.0638066 | K39: ='[3]SWA 12-5-2023'!L39 -> 474257.78 | M39: =K39+L39 -> 474257.78 | N39: =M39/$I$68*100 -> 0.90423561 | O39: On-going | R39: =G39*0.85 -> 1928.8965
A40: 103(1)a | B40: Structure Excavation | F40: cu.m. | G40: 354.11 | H40: 116.49 | I40: =ROUND(G40*H40,4) -> 41250.274 | J40: =I40/$I$68*100 -> 0.078649139 | K40: ='[3]SWA 12-5-2023'!L40 -> 24602.688 | M40: =K40+L40 -> 24602.688 | N40: =M40/$I$68*100 -> 0.0469083 | O40: On-going | R40: =[3]Sheet1!E33 -> 235 | S40: =1.2*0.8*S54 -> 211.2
A41: 103(6) | B41: Pipe Culvert and Drain Excavation | F41: cu.m. | G41: 18.25 | H41: 469.72 | I41: =ROUND(G41*H41,4) -> 8572.39 | J41: =I41/$I$68*100 -> 0.016344403 | K41: ='[3]SWA 12-5-2023'!L41 -> 13527.936 | M41: =K41+L41 -> 13527.936 | N41: =M41/$I$68*100 -> 0.025792811 | O41: On-going | R41: =(R58+R62)*(0.6+1)*1 -> 28.8 | AA41: =SUM(AA19:AA31) -> 1.8122975e+08
A42: 104(1) | B42: Embankment | F42: cu.m. | G42: 5528.47 | H42: 274.96 | I42: =ROUND(G42*H42,4) -> 1520108.1 | J42: =I42/$I$68*100 -> 2.8982885 | K42: ='[3]SWA 12-5-2023'!L42 -> 1292091.9 | M42: =K42+L42 -> 1292091.9 | N42: =M42/$I$68*100 -> 2.4635452 | O42: On-going | R42: =G42*0.85 -> 4699.1995 | AA42: 50224.1
A43: 105(1) | B43: Sub-Grade Preparation(Common Materials) | F43: sq.m. | G43: 19367.1 | H43: 18.73 | I43: =ROUND(G43*H43,4) -> 362745.78 | J43: =I43/$I$68*100 -> 0.69162313 | K43: ='[3]SWA 12-5-2023'!L43 -> 501092.87 | L43: =H43*(P43+Q43) -> 16407.48 | M43: =K43+L43 -> 517500.35 | N43: =M43/$I$68*100 -> 0.98668332 | O43: On-going | P43: =P47 -> 651 | Q43: ='3-18-22-2024'!J13 -> 225 | R43: =[3]Sheet1!N18 -> 26753.49
...

Sheet stewa
A2: Republic of the Philippines
A3: PROVINCE OF CAGAYAN
A4: Capitol Hills, Tuguegarao City
A5: PROVINCIAL ENGINEER'S OFFICE
H6: JUST FILL IN ON BLUE CELL!!!
A7: STATEMENT OF TIME ELAPSED AND WORK ACCOMPLISHED
I8: LEGEND:
B9: 45373 | G9: * | H9: To be Filled In | I9: single | J9: WITHOUT REVISION
I10: in a relationship | J10: WITH REVISION
I11: complicated | J11: ON THE EXPIRY DATE WITHOUT REVISION
A12: Project Name | C12: : | D12: ='[3]SWA 9-14-2023'!E5 -> IMPROVEMENT OF ROAD NETWORK | G12: * | H12: To be Filled In | I12: married | J12: ON THE EXPIRY DATE WITH REVISION
C13: : | D13: ='[3]SWA 9-14-2023'!E6 -> A. PADUL SOLANA TO TUAO ROAD SOLANA, CAGAYAN
C14: : | D14: ='[3]SWA 9-14-2023'!E7 -> B. BUGNAY TUAO TO SOLANA ROAD TUAO, CAGAYAN
A15: Location | C15: : | D15: ='[3]SWA 9-14-2023'!E9 -> SOLANA-TUAO, CAGAYAN | G15: * | H15: To be Filled In | I15: separated | J15: ON THE COMPLETION DATE WITHOUT REVISION
A16: Contract Amount | C16: : | D16: ='[3]SWA 12-5-2023'!I68 -> 52448475 | G16: * | H16: To be Filled In | I16: divorced | J16: ON THE COMPLETION DATE WITH REVISION
A17: Contractor | C17: : | D17: DRAGONACE CONSTRUCTION CORPORATION / | G17: * | H17: To be Filled In | I17: LDR_1 | J17: WITHOUT REVISION
D18: MG JACINTO CONSTRUCTION JOINT VENTURE | I18: LDR_2 | J18: WITH REVISION
A19: 1. | B19: Period Covered: | C19: : | D19: =D22+10 -> 45046 | E19: to
D20: =+B9 -> 45373
A21: 2. | B21: Contract Duration | C21: : | D21: =J21 -> 345 | I21: To be Filled In | J21: 345 | K21: Contract Duration
A22: 3. | B22: Date of Receipt of Notice to Proceed | C22: : | D22: 45036 | G22: * | H22: To be Filled In
A23: 4. | B23: Expiry Date | C23: : | D23: =+D19+D21-1 -> 45390
A24: 5. | B24: Approved Time Extension | C24: : | D24: =D25+J24 -> 0 | I24: To be Filled In | J24: 0 | K24: Approved Time Extension
A25: 6. | B25: Approved Time Suspension | C25: : | D25: =J25 -> 0 | I25: To be Filled In | K25: Approved Time Suspension
A26: 7. | B26: Total Time Extension | D26: =IF(J26>0,J26,0) -> 0 | I26: Don't Fill In | J26: =D24 -> 0 | K26: Total Time Extension
A27: 8. | B27: Revised Contract Duration | C27: : | D27: =IF(J26>0,J27,0) -> 0 | I27: Don't Fill In | J27: =IF(D24>0,D24+J21,0) -> 0 | K27: Revised Contract Duration | N27: \
A28: 9. | B28: Revised Expiry Date | C28: : | D28: =IF(J26>0,D23+D26,"")
A29: 10. | B29: Total Calendar days Elapsed to Date | C29: : | D29: =+D20-D19+1 -> 328
A30: 11. | B30: Percentage of work accomplished - Actual | C30: : | D30: 0.8532
A31: 12. | B31: Percentage of work accomplished -Planned | C31: : | D31: =IF(L37="F",IF(J27>0,J32,J31),IF(L37="L",IF(J27>0,J35,J34))) -> 0.95072464 | I31: Don't Fill In | J31: =(((SIN((((180*((D29))/D21)-90)*(3.14159265358979/180)))+1)*50)/100) -> 0.99402095 | K31: W/ FORMULA - Planned (WITHOUT time extension)
A32: 13. | B32: Slippage | C32: : | D32: =D30-D31 -> -0.097524638 | I32: Don't Fill In | J32: =IF(J27>0,(((SIN((((180*((D29))/D27)-90)*(3.14159265358979/180)))+1)*50)/100),"") | K32: W/ FORMULA - Planned (WITH time extension)
A33: 14. | B33: Remarks | C33: : | D33: =IF(D30<100%,"ON-GOING","COMPLETED") -> ON-GOING
I34: Don't Fill In | J34: =D29/D21 -> 0.95072464 | K34: LINEAR - Planned (WITHOUT time extension)
I35: Don't Fill In | J35: =IF(J27>0,D29/J27,"") | K35: LINEAR - Planned (WITH time extension)
B37: Submitted by: | D37: Noted : | I37: WRITE "F" - OPT TO USE FORMULA | L37: l
I38: WRITE "L" - OPT TO USE LINEAR
B40: PORFIRIO S. CANAPI | D40: ARNOLD L. MANUEL
B41: Engineer II | D41: OIC Chief - Construction Division
I42: =97.95-15.65 -> 82.3

Sheet 3 - 25-27 - 2024
A3: Contract No. | B3: B011 - 2023
A4: Project Title: | B4: Improvement of Road Network
B5: A. Padul Solana - Tuao Road Solana, Cagayan | I5: Municipality: | K5: Tuao
A6: Contractor: | B6: B. Bugnay Tuao to Solana Road Tuao, Cagayan | I6: Week Covered: | K6: March 25-27, 2024
B7: Dragonace Construction Corporation
A8: ACCOMPLISHMENT
A9: Item No. | B9: Description | G9: Location / Station | J9: Quantity for the week | L9: Unit
J10: Physical | K10: Billable
N13: =8*9 -> 72
N14: =75*1.5 -> 112.5 | O14: =102/1.5 -> 68
N15: 3
N16: =N14*3 -> 337.5
A32: FOR VARIATION ORDER
A33: Item No. | B33: Description | G33: Quantity | I33: Unit | J33: Additive | K33: Deductive | L33: New Item
A39: ACTIVITIES FOR THE WEEK: | H39: FIELD INSTRUCTIONS:
A51: PROBLEMS ENCOUNTERED/ REMARKS: | H51: MANPOWER | K51: EQUIPMENT
H52: Description | J52: Quantity | K52: Description | L52: Quantity
A64: WEEKLY PHYSICAL ACCOMPLISHMENT PERCENTAGE (CUMULATIVE):
B66: ORIG. TARGET | D66: REV. TARGET | F66: ACTUAL | H66: VARIANCE | J66: REMARKS
A70: Prepared by: | D70: Checked and Reviewed By: | H70: Noted By: | K70: Conforme:
A72: ________________________ | D72: PORFIRIO S. CANAPI | H72: ARNOLD L. MANUEL | K72: ________________________ | N72: =#REF!+1.27 -> #REF!
A73: PEO Engineer I | D73: PEO Engineer II | H73: PEO Engineer III | K73: Contractor's Representative
N76: =84.35+1.27 -> 85.62

Sheet 4 - 1-5 - 2024
A3: Contract No.
A4: Project Title: | B4: Concreting of Barangay Road, Alcala, Cagayan –
B5: Malalatan Barangay Road, Alcala, Cagayan | I5: Municipality: | K5: Alcala
A6: Contractor: | B6: M.G. Jacinto Construction | I6: Week Covered: | K6: April 1 - 5, 2024
A8: ACCOMPLISHMENT
A9: Item No. | B9: Description | G9: Location / Station | J9: Quantity for the week | L9: Unit
J10: Physical | K10: Billable
N13: =8*9 -> 72
N14: =75*1.5 -> 112.5 | O14: =102/1.5 -> 68
N15: 3
N16: =N14*3 -> 337.5
A32: FOR VARIATION ORDER
A33: Item No. | B33: Description | G33: Quantity | I33: Unit | J33: Additive | K33: Deductive | L33: New Item
A39: ACTIVITIES FOR THE WEEK: | H39: FIELD INSTRUCTIONS:
A51: PROBLEMS ENCOUNTERED/ REMARKS: | H51: MANPOWER | K51: EQUIPMENT
H52: Description | J52: Quantity | K52: Description | L52: Quantity
A64: WEEKLY PHYSICAL ACCOMPLISHMENT PERCENTAGE (CUMULATIVE):
B66: ORIG. TARGET | D66: REV. TARGET | F66: ACTUAL | H66: VARIANCE | J66: REMARKS
A70: Prepared by: | D70: Checked and Reviewed By: | H70: Noted By: | K70: Conforme:
A72: ________________________ | D72: PORFIRIO S. CANAPI | H72: ARNOLD L. MANUEL | K72: ________________________ | N72: =#REF!+1.27 -> #REF!
A73: PEO Engineer I | D73: PEO Engineer II | H73: PEO Engineer III | K73: Contractor's Representative
N76: =84.35+1.27 -> 85.62

Sheet 4 - 8-12 - 2024
A3: Contract No.
A4: Project Title: | B4: Concreting of Barangay Road, Alcala, Cagayan –
B5: Malalatan Barangay Road, Alcala, Cagayan | I5: Municipality: | K5: Alcala
A6: Contractor: | B6: M.G. Jacinto Construction | I6: Week Covered: | K6: April 8 - 12, 2024
A8: ACCOMPLISHMENT
A9: Item No. | B9: Description | G9: Location / Station | J9: Quantity for the week | L9: Unit
J10: Physical | K10: Billable
N13: =8*9 -> 72
N14: =75*1.5 -> 112.5 | O14: =102/1.5 -> 68
N15: 3
N16: =N14*3 -> 337.5
A32: FOR VARIATION ORDER
A33: Item No. | B33: Description | G33: Quantity | I33: Unit | J33: Additive | K33: Deductive | L33: New Item
A39: ACTIVITIES FOR THE WEEK: | H39: FIELD INSTRUCTIONS:
A51: PROBLEMS ENCOUNTERED/ REMARKS: | H51: MANPOWER | K51: EQUIPMENT
H52: Description | J52: Quantity | K52: Description | L52: Quantity
A64: WEEKLY PHYSICAL ACCOMPLISHMENT PERCENTAGE (CUMULATIVE):
B66: ORIG. TARGET | D66: REV. TARGET | F66: ACTUAL | H66: VARIANCE | J66: REMARKS
A70: Prepared by: | D70: Checked and Reviewed By: | H70: Noted By: | K70: Conforme:
A72: ________________________ | D72: PORFIRIO S. CANAPI | H72: ARNOLD L. MANUEL | K72: ________________________ | N72: =#REF!+1.27 -> #REF!
A73: PEO Engineer I | D73: PEO Engineer II | H73: PEO Engineer III | K73: Contractor's Representative
N76: =84.35+1.27 -> 85.62

Sheet 4 - 15-19 - 2024
A3: Contract No.
A4: Project Title: | B4: Concreting of Barangay Road, Alcala, Cagayan –
B5: Malalatan Barangay Road, Alcala, Cagayan | I5: Municipality: | K5: Alcala
A6: Contractor: | B6: M.G. Jacinto Construction | I6: Week Covered: | K6: April 15 - 19, 2024
A8: ACCOMPLISHMENT
A9: Item No. | B9: Description | G9: Location / Station | J9: Quantity for the week | L9: Unit
J10: Physical | K10: Billable
N13: =8*9 -> 72
N14: =75*1.5 -> 112.5 | O14: =102/1.5 -> 68
N15: 3
N16: =N14*3 -> 337.5
A32: FOR VARIATION ORDER
A33: Item No. | B33: Description | G33: Quantity | I33: Unit | J33: Additive | K33: Deductive | L33: New Item
A39: ACTIVITIES FOR THE WEEK: | H39: FIELD INSTRUCTIONS:
A51: PROBLEMS ENCOUNTERED/ REMARKS: | H51: MANPOWER | K51: EQUIPMENT
H52: Description | J52: Quantity | K52: Description | L52: Quantity
A64: WEEKLY PHYSICAL ACCOMPLISHMENT PERCENTAGE (CUMULATIVE):
B66: ORIG. TARGET | D66: REV. TARGET | F66: ACTUAL | H66: VARIANCE | J66: REMARKS
A70: Prepared by: | D70: Checked and Reviewed By: | H70: Noted By: | K70: Conforme:
A72: ________________________ | D72: PORFIRIO S. CANAPI | H72: ARNOLD L. MANUEL | K72: ________________________ | N72: =#REF!+1.27 -> #REF!
A73: PEO Engineer I | D73: PEO Engineer II | H73: PEO Engineer III | K73: Contractor's Representative
N76: =84.35+1.27 -> 85.62

Sheet 4 - 22-26 - 2024
A3: Contract No.
A4: Project Title: | B4: Concreting of Barangay Road, Alcala, Cagayan –
B5: Malalatan Barangay Road, Alcala, Cagayan | I5: Municipality: | K5: Alcala
A6: Contractor: | B6: M.G. Jacinto Construction | I6: Week Covered: | K6: April 22 - 26, 2024
A8: ACCOMPLISHMENT
A9: Item No. | B9: Description | G9: Location / Station | J9: Quantity for the week | L9: Unit
J10: Physical | K10: Billable
N13: =8*9 -> 72
N14: =75*1.5 -> 112.5 | O14: =102/1.5 -> 68
N15: 3
N16: =N14*3 -> 337.5
A32: FOR VARIATION ORDER
A33: Item No. | B33: Description | G33: Quantity | I33: Unit | J33: Additive | K33: Deductive | L33: New Item
A39: ACTIVITIES FOR THE WEEK: | H39: FIELD INSTRUCTIONS:
A51: PROBLEMS ENCOUNTERED/ REMARKS: | H51: MANPOWER | K51: EQUIPMENT
H52: Description | J52: Quantity | K52: Description | L52: Quantity
A64: WEEKLY PHYSICAL ACCOMPLISHMENT PERCENTAGE (CUMULATIVE):
B66: ORIG. TARGET | D66: REV. TARGET | F66: ACTUAL | H66: VARIANCE | J66: REMARKS
A70: Prepared by: | D70: Checked and Reviewed By: | H70: Noted By: | K70: Conforme:
A72: ________________________ | D72: PORFIRIO S. CANAPI | H72: ARNOLD L. MANUEL | K72: ________________________ | N72: =#REF!+1.27 -> #REF!
A73: PEO Engineer I | D73: PEO Engineer II | H73: PEO Engineer III | K73: Contractor's Representative
N76: =84.35+1.27 -> 85.62

Sheet CONCRETING
A3: Contract No.
A4: Project Title: | B4: CONSTRUCTION OF FARM TO MARKET ROAD IN THE PROVINCE OF CAGAYAN
B5: JOAQUIN DELA CRUZ FARM TO MARKET ROAD, CAMALANIUGAN | I5: Municipality: | K5: CAMALANIUGAN
A6: Contractor: | B6: RARR CONSTRUCTION | I6: Week Covered: | K6: =#REF! -> #REF!
A8: ACCOMPLISHMENT
A9: Item No. | B9: Description | G9: Location / Station | J9: Quantity for the week | L9: Unit
J10: Physical | K10: Billable
A11: I | B11: OTHER GENERAL REQUIREMENTS
A12: B.5 | B12: Project Billboard | L12: each
A13: B.7 | B13: Construction Safety and Health Program | L13: l.s
A14: B.9 | B14: Mobilization/ Demobilization | L14: l.s
A15: II | B15: EARTHWORKS
A16: 102(2) | B16: Surplus Common Excavation | L16: cu.m
A17: 104(1)a | B17: Embankment from Roadway Excavation (Common Soil) | L17: cu.m
A18: 105(1)a | B18: Sub-grade Preparation (Common Materials) | L18: sq.m.
A19: III | B19: SUB-BASE COURSE
A20: 200(1) | B20: Aggregate Sub-base Course | L20: cu.m
A21: IV | B21: SUB-BASE COURSE
A22: 311(1)c1 | B22: Portland Cement Concrete Pavement (Unreinforced), 230mm thk. | L22: sq.m.
A34: FOR VARIATION ORDER
A35: Item No. | B35: Description | G35: Quantity | I35: Unit | J35: Additive | K35: Deductive | L35: New Item
A41: ACTIVITIES FOR THE WEEK: | H41: FIELD INSTRUCTIONS:
A53: PROBLEMS ENCOUNTERED/ REMARKS: | H53: MANPOWER | K53: EQUIPMENT
H54: Description | J54: Quantity | K54: Description | L54: Quantity
A66: WEEKLY PHYSICAL ACCOMPLISHMENT PERCENTAGE (CUMULATIVE):
B68: ORIG. TARGET | D68: REV. TARGET | F68: ACTUAL | H68: VARIANCE | J68: REMARKS
A72: Prepared by: | D72: Checked and Reviewed By: | H72: Noted By: | K72: Conformed by:
A74: GLORY VEE A. ARIBBAY | D74: MARK KEVIN B. MARTIN | H74: ARNOLD L. MANUEL | K74: ____________________________
A75: PEO Engineer I | D75: PEO Engineer II | H75: PEO Engineer III | K75: Contractor's Representative
A81: Contract No.
A82: Project Title: | B82: CONSTRUCTION OF LINE DRAINAGE AT REAL DE HOOD
B83: PROVINCIAL ROAD | I83: Municipality: | K83: CAMALANIUGAN
A84: Contractor: | B84: INFRAPRO CONSTRUCTION | I84: Week Covered: | K84: JUNE 17-21, 2024
A86: ACCOMPLISHMENT
A87: Item No. | B87: Description | G87: Location / Station | J87: Quantity for the week | L87: Unit
J88: Physical | K88: Billable
A110: FOR VARIATION ORDER
A111: Item No. | B111: Description | G111: Quantity | I111: Unit | J111: Additive | K111: Deductive | L111: New Item
A117: ACTIVITIES FOR THE WEEK: | H117: FIELD INSTRUCTIONS:
A129: PROBLEMS ENCOUNTERED/ REMARKS: | H129: MANPOWER | K129: EQUIPMENT
...

Sheet Asassi
A3: Contract No.
A4: Project Title: | B4: Infrastructure Development for Public Schools - Construction of Multipurpose Building - Gymnasium Asassi Integrated School
I5: Municipality: | L5: BAGGAO, CAGAYAN
A6: Contractor: | B6: RJR'S Construction | I6: Week Covered:
A8: ACCOMPLISHMENT
A9: Item No. | B9: Description | G9: Location / Station | J9: Quantity for the week | M9: Unit
J10: Physical | L10: Billable
A11: I | B11: OTHER GENERAL REQUIREMENTS
A12: B.5 | B12: Project Billboard | M12: Each
A13: B.7 | B13: Construction Safety & Health Program | M13: L.S.
A14: B.9 | B14: Mobilization/Demobilization | M14: L.S.
A15: II | B15: Work Items
A16: 802 | B16: Excavation | M16: cu.m
A17: 804(a) | B17: Backfilling | M17: cu.m
A18: 804(b) | B18: Gravel Bedding | M18: cu.m
A19: 900 | B19: Reinforced Concrete | M19: cu.m
A20: 902 | B20: Reinforcing Steel Bars | M20: kg
A21: 903 | B21: Formworks and Falseworks | M21: sq.m
A22: 1046 | B22: Masonry Works | M22: sq.m
A23: 1027 | B23: Cement Plaster finish | M23: sq.m
A24: 1032 | B24: Painting Works | M24: sq.m
A25: 1047 | B25: Metal structure | M25: kg
A26: 1014 | B26: Pre-Painted Metal Sheets | M26: sq.m
A27: 1100 | B27: Conduit, Boxes & Fittings | M27: lump sum
A28: 1101 | B28: Wires and Wiring Devices | M28: lump sum
A29: 1102 | B29: Power Load Center, Switchgear and panelboards, and Other Overcurrent Protection Devices | M29: lot
A31: 1103 | B31: Lighting Fixtures and Lamps | M31: lot
A32: 1109 | B32: Grounding System | M32: lot
A45: FOR VARIATION ORDER
A46: Item No. | B46: Description | G46: Quantity | I46: Unit | J46: Additive | L46: Deductive | M46: New Item
A52: ACTIVITIES FOR THE WEEK: | H52: FIELD INSTRUCTIONS:
A64: PROBLEMS ENCOUNTERED/ REMARKS: | H64: MANPOWER | L64: EQUIPMENT
H65: Description | J65: Quantity | L65: Description | M65: Quantity
A77: WEEKLY PHYSICAL ACCOMPLISHMENT PERCENTAGE (CUMULATIVE):
B79: ORIG. TARGET | D79: REV. TARGET | F79: ACTUAL | H79: VARIANCE | J79: REMARKS
A83: Prepared by: | D83: Checked and Reviewed By: | H83: Noted By: | L83: Conformed by:
A85: LIZA P. NIDUA | D85: DIXIE R. CABRERA | H85: ARNOLD L. MANUEL
A86: PEO Engineer I | D86: PEO Engineer II | H86: PEO Engineer III | L86: Contractor's Representative
A92: Contract No.
A93: Project Title: | B93: CONSTRUCTION OF LINE DRAINAGE AT REAL DE HOOD
...

Sheet PHO Phase II
A3: Contract No.
A4: Project Title: | B4: Construction of Various Infrastructure Projects Upgrading/Improvement of
B5: Provincial Health office Phase II, Capitol Compound, Tuguegarao City | I5: Municipality: | L5: TUGUEGARAO CITY, CAGAYAN
A6: Contractor: | B6: Genten Builders | I6: Week Covered:
A8: ACCOMPLISHMENT
A9: Item No. | B9: Description | G9: Location / Station | J9: Quantity for the week | M9: Unit
J10: Physical | L10: Billable
A11: I | B11: OTHER GENERAL REQUIREMENTS
A12: B.5 | B12: Project Billboard | M12: set
A13: B.7 | B13: Construction safety & Health Program | M13: l.s
A14: B.9 | B14: Mobilization/Demobilization | M14: lot
A15: II | B15: WORK ITEMS
A16: 803 | B16: Structure Excavation | M16: cu.m
A17: 804(1) | B17: Embankment | M17: cu.m
A18: 900(a) | B18: Reinforced Concrete Works for Column Footing | M18: cu.m
A19: 900(b) | B19: Reinforced Concrete Works for Column | M19: cu.m
A20: 900(c) | B20: Reinforced Concrete Works for Slab | M20: cu.m
A21: 900(d) | B21: Reinforced Concrete Works for Tie Beam | M21: cu.m
A22: 900(e) | B22: Reinforced Concrete Works for Roof Beam | M22: cu.m
A23: 900(f) | B23: Reinforced Concrete Works for Handhole & Encasement | M23: cu.m
A24: 903 | B24: Formworks and Falseworks | M24: bd.ft
A25: 1046 | B25: Masonry Works | M25: sq.m
A26: 1027(1) | B26: Cement Plaster Finish | M26: sq.m
A27: 1014 | B27: Pre-Painted Metal Sheets | M27: sq.m
A28: 1016 | B28: Waterproofing | M28: sq.m
A29: 1032(1)a | B29: Painting Works (Masonry and Concrete) | M29: sq.m
A30: 1032(1)b | B30: Painting Works (Ficem Board) | M30: sq.m
A31: 1003(1)e1 | B31: Ceiling Metal Frame Ficem Board | M31: sq.m
A32: 1007(1)b | B32: Aluminum Framed Glass Door | M32: lot
A33: 1008 | B33: Aluminum Glass Window | M33: sq.m
A34: 1018(1) | B34: Ceramic Tiles | M34: sq.m
A35: 1100 | B35: Conduit, Boxes & Fittings | M35: lot
A36: 1101 | B36: Wires and Wiring Devices | M36: lot
A37: 1102 | B37: Power Load Center, Switchgear and Panelboards, and Other | M37: lot
A38: 1103 | B38: Lighting Fixtures and Lamps | M38: lot
A39: 1109 | B39: Grounding System | M39: lot | O39: a
A40: 1002 | B40: Plumbing Works | M40: lot
A44: FOR VARIATION ORDER
A45: Item No. | B45: Description | G45: Quantity | I45: Unit | J45: Additive | L45: Deductive | M45: New Item
A51: ACTIVITIES FOR THE WEEK: | H51: FIELD INSTRUCTIONS:
...

Sheet Gas Station
A3: Contract No.
A4: Project Title: | B4: Construction of Gas Station at Capitol Compound, Tuguegarao City
I5: Municipality: | L5: TUGUEGARAO CITY, CAGAYAN
A6: Contractor: | B6: San Jacinto Construction Services | I6: Week Covered:
A8: ACCOMPLISHMENT
A9: Item No. | B9: Description | G9: Location / Station | J9: Quantity for the week | M9: Unit
J10: Physical | L10: Billable
A11: I | B11: OTHER GENERAL REQUIREMENTS
A12: B.5 | B12: Project Billboard | M12: each
A13: B.7 | B13: Construction Safety & Health Program | M13: l.s
A14: B.9 | B14: Mobilization/Demobilization | M14: l.s
A15: II | B15: WORK ITEMS
A16: 606 b | B16: Pavement markings | M16: sq.m
A17: 627 | B17: Concrete bollard/protection post | M17: l.s
A18: 801a | B18: Removal of Structures/Obstruction | M18: sq.m
A19: 801b | B19: Removal of Structures/Obstruction | M19: each
A20: 801c | B20: Relocation of Utilities | M20: l.s
A21: 803 | B21: Structure Excavation | M21: cu.m
A22: 804(a) | B22: Embankment | M22: cu.m
A23: 804(b) | B23: Gravel Bed | M23: cu.m
A24: 900a | B24: Reinforced Concrete (Foundation) | M24: cu.m
A25: 900b | B25: Reinforced Concrete (Column) | M25: cu.m
A26: 900c | B26: Reinforced Concrete (Grade Beam) | M26: cu.m
A27: 900d | B27: Reinforced Concrete (Beam-01) | M27: cu.m
A28: 900e | B28: Reinforced Concrete (Corbel) | M28: cu.m
A29: 900f | B29: Reinforced Concrete (Pump Island Slab on Fill) | M29: cu.m
A30: 900g | B30: Reinforced Concrete (Tank Pavement Slab on Fill) | M30: cu.m
A31: 900h | B31: Reinforced Concrete (Cashier Booth Roof Slba) | M31: cu.m
A32: 900i | B32: Reinforced Concrete (Wall Footing) | M32: cu.m
A33: 900j | B33: Reinforced Concrete (MDP TRENCHWAY) | M33: cu.m
A34: 900k | B34: Reinforced Concrete (Vent Riser Pipe Transition) | M34: cu.m
A35: 903 | B35: Formworks and Falseworks | M35: sq.m
A36: 1001 | B36: Storm Drainage and Seewerage System | M36: l.m
A37: 1003 | B37: Carpentry and Joinery Works | M37: sq.m
A38: 1004 | B38: Finishing Hardware | M38: sq.m
A39: 1005 | B39: Louver Window | M39: sq.m
A40: 1007 | B40: Aluminum Framed Glass Door | M40: l.s
A41: 1008 | B41: Aluminum Glass Windows | M41: sq.m
A42: 1011(1)b | B42: Roll-Up Doors | M42: l.s
A43: 1014 | B43: Prepainted Metal Sheets | M43: sq.m
...

Sheet FMR Road
A3: Contract No.
A4: Project Title: | B4: Improvement/Concreting of Roads - Concreting of the Portion of FMR Road
B5: at Barangay Baculud, Amulung, Cagayan | I5: Municipality: | L5: AMULUNG, CAGAYAN
A6: Contractor: | B6: MIG Aggregates and Concrete Products | I6: Week Covered:
A8: ACCOMPLISHMENT
A9: Item No. | B9: Description | G9: Location / Station | J9: Quantity for the week | M9: Unit
J10: Physical | L10: Billable
A11: I | B11: FACILITIES FOR ENGINEERS
A12: A.1.1 (11) | B12: Provision of Furnitures/Fixtures, Equipment & Appliances for the Field Office for the Engineer | M12: L.S
A14: II | B14: OTHER GENERAL REQUIREMENTS
A15: B.5 | B15: Project Billboard | M15: Each
A16: B.7 | B16: Construction Safety & Health Program | M16: L.S
A17: B.9 | B17: Mobilization/Demobilization | M17: L.S
A18: III | B18: EARTHWORKS
A19: 101(4)a1 | B19: Removal of Actual Structures/Obstruction (610mmØ RCPC) | M19: ln.m
A20: 101(4)a3 | B20: Removal of Actual Structures/Obstruction (910mmØ RCPC) | M20: ln.m
A21: 102(2) | B21: Roadway Excavation (Surplus Common Excavation) | M21: cu.m
A22: 103(1)a | B22: Structure Excavation (Common Soil) | M22: cu.m
A23: 103(6)a | B23: Pipe Culvert and Drain Excavation (Common Soil) | M23: cu.m
A24: 104(1)a | B24: Embankment from Roadway Excavation | M24: cu.m
A25: 105(1) | B25: Sub-Grade Preparation (Common Soil) | M25: sq.m
A26: IV | B26: SUB-BASE COURSE
A27: 200(1) | B27: Aggregate Sub-Base Course | M27: cu.m
A28: V | B28: SURFACE COURSE
A29: 311(1)c1 | B29: Portland Cement Concrete Pavemnet (Unreinforced) | M29: sq.m
B30: 230mm thk.
A31: 311(2)e1 | B31: Portland Cement Concrete Pavemnet (Reinforced) | M31: sq.m
B32: 0.28m thk.
A33: VI | B33: DRAINAGE AND SLOPE PROTECTION
A34: 1 | B34: Retaining Wall
A35: 404(1)a | B35: Reinforcing Steel, Grade 40 (Retaining Wall) | M35: kgs.
A36: 404(1)b | B36: Reinforcing Steel, Grade 60 (Retaining wall) | M36: kgs.
A37: 405(1)a3 | B37: Structural Concrete Class A (Retaining Wall) | M37: cu.m
A38: 2 | B38: Reinforced Concrete Box Culvert (Single Barrel)
A39: 404(1)a | B39: Reinforcing Steel, Grade 40 (RCBC Single Barrel) | M39: kgs.
A40: 404(1)b | B40: Reinforcing Steel, Grade 60 (RCBC Single Barrel) | M40: kgs.
A41: 405(1)a3 | B41: Structural Concrete Class A (RCBC Single Barrel) | M41: cu.m
A42: 3 | B42: Reinforced Concrete Pipe Culvert
A43: 404(1)a | B43: Reinforcing Steel, Grade 40 (610mmØ RCPC) | M43: kgs
A44: 404(1)b | B44: Reinforcing Steel, Grade 60 (610mmØ RCPC) | M44: kgs
...

Sheet Warehouse
A3: Contract No.
A4: Project Title: | B4: Improvement of PEO Warehouse, Capitol Compound, Tuguegarao City
I5: Municipality: | L5: TUGUEGARAO CITY, CAGAYAN
A6: Contractor: | B6: WBS Construction and Construction Supply | I6: Week Covered:
A8: ACCOMPLISHMENT
A9: Item No. | B9: Description | G9: Location / Station | J9: Quantity for the week | M9: Unit
J10: Physical | L10: Billable
A11: I | B11: OTHER GENERAL REQUIREMENTS
A12: B.5 | B12: Project Billboard | M12: Each
A13: B.7 | B13: Construction Safety & Health Program | M13: L.S
A14: B.9 | B14: Mobilization/Demobilization | M14: L.S
A15: II | B15: WORK ITEMS
A16: 801(3)a | B16: Removal of Actual Structures/Obstruction | M16: lot
A17: 804(4) | B17: Gravel Fill | M17: cu.m
A18: 900a | B18: Reinforced Concrete (Slab on Grade) | M18: cu.m
A19: 900b | B19: Reinforced Concrete (Septic Tank) | M19: cu.m
A20: 900c | B20: Reinforced Concrete (Countertop Slab and Ledge) | M20: cu.m
A21: 903(1) | B21: Formworks and Falseworks | M21: L.S
A22: 1046 | B22: Masonry Works | M22: sq.m
A23: 1027(1) | B23: Cement Plaster Finish | M23: sq.m
A24: 1018 | B24: Ceramic Tile Works | M24: sq.m
A25: 1003(1) | B25: Ceiling | C25: . | M25: sq.m
A26: 1032 | B26: Painting, Varnishing & Other Related Works | M26: sq.m
A27: 1002 | B27: Plumbing Works | M27: lot
A28: 1010 | B28: Doors | M28: sq.m
A29: 1008(1) | B29: Aluminum Glass Windows | M29: sq.m
A30: 1100 | B30: Conduit, Boxes & Fittings | M30: l.s
A31: 1101 | B31: Wires and Wiring Devices | M31: l.s
A32: 1102(a) | B32: Power Load Center, Switchgear and Panelboards, | M32: l.s
B33: and other Overcurrent Protection Devices
A34: 1103 | B34: Lighting Fixtures and Lamps | M34: l.s
A49: Item No. | B49: Description | G49: Quantity | I49: Unit | J49: Additive | L49: Deductive | M49: New Item
A55: ACTIVITIES FOR THE WEEK: | H55: FIELD INSTRUCTIONS:
A67: PROBLEMS ENCOUNTERED/ REMARKS: | H67: MANPOWER | L67: EQUIPMENT
H68: Description | J68: Quantity | L68: Description | M68: Quantity
A80: WEEKLY PHYSICAL ACCOMPLISHMENT PERCENTAGE (CUMULATIVE):
B82: ORIG. TARGET | D82: REV. TARGET | F82: ACTUAL | H82: VARIANCE | J82: REMARKS
A86: Prepared by: | D86: Checked and Reviewed By: | H86: Noted By: | L86: Conformed by:
A88: LIZA P. NIDUA | D88: DIXIE R. CABRERA | H88: ARNOLD L. MANUEL
A89: PEO Engineer I | D89: PEO Engineer II | H89: PEO Engineer III | L89: Contractor's Representative
...

Sheet Kamaranan
A3: Contract No.
A4: Project Title: | B4: Improvement of Provincial Government of Cagayan - Repair/Rehabilitation/
B5: Improvement of Kamaranan Building, Capitol Compounds, Tuguegarao City | I5: Municipality: | L5: TUGUEGARAO CITY, CAGAYAN
A6: Contractor: | B6: San Jacinto Construction Services | I6: Week Covered:
A8: ACCOMPLISHMENT
A9: Item No. | B9: Description | G9: Location / Station | J9: Quantity for the week | M9: Unit
J10: Physical | L10: Billable
A11: I | B11: OTHER GENERAL REQUIREMENTS
A12: B.5 | B12: Project Billboard, Signages and Barricades | M12: each
A13: B.7 | B13: Construction Safety & Health Program | M13: lot
A14: B.9 | B14: Mobilization/Demobilization | M14: lot
A15: II | B15: WORK ITEMS
A16: 801 | B16: Removal of Structures/Obstructions | M16: sq.m
A17: 804(a) | B17: Embankment | M17: cu.m
A18: 804(b) | B18: Gravel Bed | M18: cu.m
A19: 900(a) | B19: Reinforced Concrete for Pedestal & Countertop | M19: cu.m
A20: 900(b) | B20: Reinforced Concrete for Wall Footing | M20: cu.m
A21: 900(c) | B21: Reinforced Concrete for Slab on Fill | M21: cu.m
A22: 1046 | B22: Masonry Works | M22: sq.m
A23: 1027 | B23: Cement Plaster Finish | M23: sq.m
A24: 1047 | B24: Metal Structures | M24: kgs
A25: 1014(1)a2 | B25: Pre-Painted Metal Sheets | M25: sq.m
A26: 1012 | B26: Sheet Glass | M26: sq.m
A27: 1007(1)b | B27: Aluminum Framed Glass Door | M27: sq.m
A28: 1008 | B28: Aluminum Glass Window | M28: sq.m
A29: 1010 | B29: Wooden Doors | M29: set
A30: 1018 | B30: Ceramic Tiles | M30: sq.m
A31: 1032 | B31: Painting Works | M31: sq.m
A32: 1016(1)a | B32: Waterproofing | M32: sq.m
A33: 1003(1)a1 | B33: Carpentry and Joinery Works (Ceiling - Fiber Cement Board) | M33: sq.m
A34: 1003(1)e2 | B34: Carpentry and Joinery Works (Ceiling-Pre-painted Metal Panel) | M34: sq.m
A35: 1003(2) | B35: Carpentry and Joinery Works (Cubicle Partition Wall) | M35: sq.m
A36: 1003(3) | B36: Carpentry and Joinery Works (Cabinet) | M36: sq.m
A37: 1002 | B37: Plumbing Works | M37: lot
A38: 1200(5) | B38: Exhaust Fan | M38: set
A39: SPL | B39: Finishing Works | M39: lot
A40: 1100 | B40: Conduit,Boxes and Fittings | M40: lot
A41: 1101 | B41: Wire and Wiring Devices | M41: lot
A42: 1102 | B42: Power Load Center, Switchgear and Panelboards and | M42: l.s
A43: 1103 | B43: Lighting and Fixture Lamps | M43: l.s
...

Sheet Vicente
A3: Contract No.
A4: Project Title: | B4: Repair of Vicente Trinidad National High School Gymasium, Iguig, Cagayan
I5: Municipality: | L5: IGUIG, CAGAYAN
A6: Contractor: | B6: TS Construction | I6: Week Covered:
A8: ACCOMPLISHMENT
A9: Item No. | B9: Description | G9: Location / Station | J9: Quantity for the week | M9: Unit
J10: Physical | L10: Billable
A11: I | B11: OTHER GENERAL REQUIREMENTS
A12: B.5 | B12: Project Billboard | M12: Each
A14: B.7 | B14: Construction Safety & Health Program | M14: L.S
A15: B.9 | B15: Mobilization/Demobilization | M15: L.S
A16: II | B16: WORK ITEMS
A17: 801(3)a | B17: Removal of Actual Structures/Obstruction | M17: sq.m
A18: 405(1) | B18: Structural Concrete | M18: cu.m
A19: 1032 | B19: Painting Works | M19: sq.m
A20: 1047 | B20: Metal Structure | M20: kg
A21: 1014 | B21: Pre-Painted Metal Sheets | M21: sq.m
A22: 1103 | B22: Electrical Works | M22: units
A32: Item No. | B32: Description | G32: Quantity | I32: Unit | J32: Additive | L32: Deductive | M32: New Item
A38: ACTIVITIES FOR THE WEEK: | H38: FIELD INSTRUCTIONS:
A50: PROBLEMS ENCOUNTERED/ REMARKS: | H50: MANPOWER | L50: EQUIPMENT
H51: Description | J51: Quantity | L51: Description | M51: Quantity
A63: WEEKLY PHYSICAL ACCOMPLISHMENT PERCENTAGE (CUMULATIVE):
B65: ORIG. TARGET | D65: REV. TARGET | F65: ACTUAL | H65: VARIANCE | J65: REMARKS
A69: Prepared by: | D69: Checked and Reviewed By: | H69: Noted By: | L69: Conformed by:
A71: LIZA P. NIDUA | D71: DIXIE R. CABRERA | H71: ARNOLD L. MANUEL
A72: PEO Engineer I | D72: PEO Engineer II | H72: PEO Engineer III | L72: Contractor's Representative
A78: Contract No.
A79: Project Title: | B79: CONSTRUCTION OF LINE DRAINAGE AT REAL DE HOOD
B80: PROVINCIAL ROAD | I80: Municipality: | L80: CAMALANIUGAN
A81: Contractor: | B81: INFRAPRO CONSTRUCTION | I81: Week Covered: | L81: JUNE 17-21, 2024
A83: ACCOMPLISHMENT
A84: Item No. | B84: Description | G84: Location / Station | J84: Quantity for the week | M84: Unit
J85: Physical | L85: Billable
A107: FOR VARIATION ORDER
A108: Item No. | B108: Description | G108: Quantity | I108: Unit | J108: Additive | L108: Deductive | M108: New Item
A114: ACTIVITIES FOR THE WEEK: | H114: FIELD INSTRUCTIONS:
A126: PROBLEMS ENCOUNTERED/ REMARKS: | H126: MANPOWER | L126: EQUIPMENT
H127: Description | J127: Quantity | L127: Description | M127: Quantity
A139: WEEKLY PHYSICAL ACCOMPLISHMENT PERCENTAGE (CUMULATIVE):
...

Sheet Budget
A3: Contract No.
A4: Project Title: | B4: Improvement of Provincial Capitol, Tuguegarao City
B5: Improvement of Provincial Budget Office | I5: Municipality: | L5: TUGUEGARAO CITY, CAGAYAN
A6: Contractor: | B6: Malaya Architecture Creatives | I6: Week Covered:
A8: ACCOMPLISHMENT
A9: Item No. | B9: Description | G9: Location / Station | J9: Quantity for the week | M9: Unit
J10: Physical | L10: Billable
A11: I | B11: OTHER GENERAL REQUIREMENTS
A12: B.5 | B12: Project Billboard | M12: each
A13: B.7 | B13: Construction safety & Health Program | M13: l.s
A14: B.9 | B14: Mobilization/Demobilization | M14: l.s
A15: II | B15: WORK ITEMS
A16: 801 | B16: Removal of Actual Structures/Obstructions | M16: sq.m
A17: 1018 | B17: Ceramic Tile Works | M17: sq.m
A18: 1003 | B18: Carpentry and Joinery Works (Ceiling) | M18: sq.m
A19: 1032 | B19: Painting, Varnishing & Other Related Works | M19: sq.m
A20: 1002 | B20: Plumbing Works | M20: lot
A21: 1010(2)b | B21: Doors - Wood Panel | M21: set
A22: 1007 | B22: Aluminum Framed Glass Door | M22: sq.m
A23: 1012 | B23: Glass and Glazing | M23: lot
A24: 1014 | B24: Pre-Painted Metal Sheets | M24: sq.m
A25: 1000(2) | B25: Wood Preservative | M25: sq.m
A26: SPL-0T | B26: Wall Finishes | M26: sq.m
A27: 1100 | B27: Conduit, Boxes & Fittings | M27: l.s
A28: 1101 | B28: Wires and Wiring Devices | M28: l.s
A29: 1102 | B29: Power Load Center, Switchgear and Panelboards, and | M29: lot
B30: Other Overcurrent Protection Devices
A31: 1103 | B31: Lighting Fixtures and Lamps | M31: l.s
A32: 1105 | B32: Network Cabling System | M32: lump sum
A33: 1200 | B33: Ventilating System | M33: lump sum
A34: 1208 | B34: Fire Alarm System | M34: lump sum
A45: FOR VARIATION ORDER
A46: Item No. | B46: Description | G46: Quantity | I46: Unit | J46: Additive | L46: Deductive | M46: New Item
A52: ACTIVITIES FOR THE WEEK: | H52: FIELD INSTRUCTIONS:
A64: PROBLEMS ENCOUNTERED/ REMARKS: | H64: MANPOWER | L64: EQUIPMENT
H65: Description | J65: Quantity | L65: Description | M65: Quantity
A77: WEEKLY PHYSICAL ACCOMPLISHMENT PERCENTAGE (CUMULATIVE):
B79: ORIG. TARGET | D79: REV. TARGET | F79: ACTUAL | H79: VARIANCE | J79: REMARKS
A83: Prepared by: | D83: Checked and Reviewed By: | H83: Noted By: | L83: Conformed by:
A85: LIZA P. NIDUA | D85: DIXIE R. CABRERA | H85: ARNOLD L. MANUEL
...

Sheet Accountant
A3: Contract No.
A4: Project Title: | B4: Improvement of Provincial Capitol, Tuguegarao City
B5: Improvement of Provincial Accountant's Office | I5: Municipality: | L5: TUGUEGARAO CITY, CAGAYAN
A6: Contractor: | B6: Malaya Architecture Creatives | I6: Week Covered:
A8: ACCOMPLISHMENT
A9: Item No. | B9: Description | G9: Location / Station | J9: Quantity for the week | M9: Unit
J10: Physical | L10: Billable
A11: I | B11: OTHER GENERAL REQUIREMENTS
A12: B.5 | B12: Project Billboard | M12: each
A13: B.7 | B13: Construction safety & Health Program | M13: l.s
A14: B.9 | B14: Mobilization/Demobilization | M14: lot
A15: II | B15: WORK ITEMS
A16: 801 | B16: Removal of Actual Structures/Obstructions | M16: sq.m
A17: 1027(1) | B17: Cement Plaster Finish | M17: sq.m
A18: 1046 | B18: Masonry Works | M18: sq.m
A19: 1018 | B19: Ceramic Tile Works | M19: sq.m
A20: 1003(1) | B20: Carpentry and Joinery Works (Ceiling) | M20: sq.m
A21: 1032(1)a | B21: Painting, Varnishing & Other Related Works | M21: sq.m
A22: 1002 | B22: Plumbing Works | M22: lot
A23: 1010 | B23: Doors | M23: set
A24: 1007 | B24: Aluminum Framed Glass Door | M24: sq.m
A25: 1014 | B25: Pre-Painted Metal Sheets | M25: sq.m
A26: 1012 | B26: Glass and Glazing | M26: sq.m
A27: 1000(2) | B27: Wood Preservative | M27: sq.m
A28: SPL-01 | B28: Wall Finishes | M28: sq.m
A29: 1100 | B29: Conduit, Boxes & Fittings | M29: lot
A30: 1101 | B30: Wires and Wiring Devices | M30: l.s
A31: 1102 | B31: Power Load Center, Switchgear and Panelboards, and | M31: lot
B32: Other Overcurrent, Protection Devices
A33: 1103 | B33: Lighting Fixtures and Lamps | M33: l.s
A34: 1200(b) | B34: Ventilating System | M34: lump sum
A35: 1208 | B35: Fire Alarm System | M35: lump sum
A36: 1105 | B36: Network Cabling System | M36: lot
A45: FOR VARIATION ORDER
A46: Item No. | B46: Description | G46: Quantity | I46: Unit | J46: Additive | L46: Deductive | M46: New Item
A52: ACTIVITIES FOR THE WEEK: | H52: FIELD INSTRUCTIONS:
A64: PROBLEMS ENCOUNTERED/ REMARKS: | H64: MANPOWER | L64: EQUIPMENT
H65: Description | J65: Quantity | L65: Description | M65: Quantity
A77: WEEKLY PHYSICAL ACCOMPLISHMENT PERCENTAGE (CUMULATIVE):
B79: ORIG. TARGET | D79: REV. TARGET | F79: ACTUAL | H79: VARIANCE | J79: REMARKS
...

Sheet Assessor
A3: Contract No.
A4: Project Title: | B4: Improvement of Provincial Assessor's Record's Room b.) Expansion of
B5: Provincial Assessor's Records Room Capitol Compound, Tuguegarao City | I5: Municipality: | L5: TUGUEGARAO CITY, CAGAYAN
A6: Contractor: | B6: Shasha's Construction and Supply | I6: Week Covered:
A8: ACCOMPLISHMENT
A9: Item No. | B9: Description | G9: Location / Station | J9: Quantity for the week | M9: Unit
J10: Physical | L10: Billable
A11: B.5 | B11: Project Billboard | M11: each
A12: B.7 | B12: Construction Safety and Health Program | M12: lumpsum
A13: B.9 | B13: Mobilization/Demobilization | M13: lumpsum
A14: 1032(1) | B14: Painting Works | M14: sq.m
A15: 1046(1) | B15: Masonry Works | M15: sq.m
A16: 1027(1) | B16: Cement Plaster Finish | M16: sq.m
A17: 1200(a) | B17: Airconditioning and Ventilating System | M17: lumpsum
A18: 1003(1) | B18: Carpentry and Joinery Works | M18: sq.m
A19: 900(1) | B19: Reinforced Concrete for Slab on Fill | M19: cu.m
A20: 1010(2) | B20: Doors | M20: sq.m
A21: 1007(1)a | B21: Aluminum Framed Glass Door | M21: sq.m
A22: 1018(2) | B22: Ceramic Tiles | M22: sq.m
A23: 804 | B23: Embankment | M23: cu.m
A24: 1700(2) | B24: Clearing and Grubbing | M24: lumpsum | N24: ,
A25: 1102(1) | B25: Panel Board with Main and Branch Breakers | M25: lumpsum
A26: 1101 | B26: Wires and Devices | M26: lot
A27: 1103 | B27: Lighting Fixtures and Lamps | M27: lot
A28: 1100 | B28: Conduit, Boxes and Fittings | M28: lot
A29: 1002 | B29: Plumbing Works | M29: lot
A30: 1005(5) | B30: Steel Windows | M30: lumpsum
A31: 1005(6) | B31: Window Accessories | M31: lumpsum
A32: 1003(1) | B32: Cabinets | M32: each
A39: FOR VARIATION ORDER
A40: Item No. | B40: Description | G40: Quantity | I40: Unit | J40: Additive | L40: Deductive | M40: New Item
A46: ACTIVITIES FOR THE WEEK: | H46: FIELD INSTRUCTIONS:
A58: PROBLEMS ENCOUNTERED/ REMARKS: | H58: MANPOWER | L58: EQUIPMENT
H59: Description | J59: Quantity | L59: Description | M59: Quantity
A71: WEEKLY PHYSICAL ACCOMPLISHMENT PERCENTAGE (CUMULATIVE):
B73: ORIG. TARGET | D73: REV. TARGET | F73: ACTUAL | H73: VARIANCE | J73: REMARKS
A77: Prepared by: | D77: Checked and Reviewed By: | H77: Noted By: | L77: Conformed by:
A79: LIZA P. NIDUA | D79: DIXIE R. CABRERA | H79: ARNOLD L. MANUEL
A80: PEO Engineer I | D80: PEO Engineer II | H80: PEO Engineer III | L80: Contractor's Representative
A86: Contract No.
...
