Workbook
Name _nhm: '[1]BACOLOD RENTAL RATES'!#REF!
Name AggPlant100.T: '[1]BACOLOD RENTAL RATES'!#REF!
Name AshDist3000.T: '[1]BACOLOD RENTAL RATES'!#REF!
Name AshPaver88.T: '[1]BACOLOD RENTAL RATES'!#REF!
Name AshPlant100.T: '[1]BACOLOD RENTAL RATES'!#REF!
Name AshPlant30.T: '[1]BACOLOD RENTAL RATES'!#REF!
Name AshPlant60.T: '[1]BACOLOD RENTAL RATES'!#REF!
Name Backhoe.63m3.T: '[1]BACOLOD RENTAL RATES'!#REF!
Name Backhoe.76m3.T: '[1]BACOLOD RENTAL RATES'!#REF!
Name Backhoe1.18m3.T: '[1]BACOLOD RENTAL RATES'!#REF!
Name Backhoe1.98m3.T: '[1]BACOLOD RENTAL RATES'!#REF!
Name Bender50.T: '[1]BACOLOD RENTAL RATES'!#REF!
Name Breaker5hp.T: '[1]BACOLOD RENTAL RATES'!#REF!
Name ChainSaw.T: '[1]BACOLOD RENTAL RATES'!#REF!
Name Comp150.T: '[1]BACOLOD RENTAL RATES'!#REF!
Name Comp350.T: '[1]BACOLOD RENTAL RATES'!#REF!
Name Comp500.T: '[1]BACOLOD RENTAL RATES'!#REF!
Name Compactor12hp.T: '[1]BACOLOD RENTAL RATES'!#REF!
Name ConcCtr30.T: '[1]BACOLOD RENTAL RATES'!#REF!
Name ConcPaver120hp.T: '[1]BACOLOD RENTAL RATES'!#REF!
Name ConcPlant30.T: '[1]BACOLOD RENTAL RATES'!#REF!
Name ConcPlant40.T: '[1]BACOLOD RENTAL RATES'!#REF!
Name ConcPlant60.T: '[1]BACOLOD RENTAL RATES'!#REF!
Name ConcPump40.T: '[1]BACOLOD RENTAL RATES'!#REF!
Name ConcPump45.T: '[1]BACOLOD RENTAL RATES'!#REF!
Name conduits: '[2]BACOLOD RENTAL RATES'!#REF!
Name Crane10t.T: '[1]BACOLOD RENTAL RATES'!#REF!
Name Crane120t.T: '[1]BACOLOD RENTAL RATES'!#REF!
Name Crane15t.T: '[1]BACOLOD RENTAL RATES'!#REF!
Name Crane20t.T: '[1]BACOLOD RENTAL RATES'!#REF!
Name Crane25t.T: '[1]BACOLOD RENTAL RATES'!#REF!
Name Crane2t.T: '[1]BACOLOD RENTAL RATES'!#REF!
Name Crane40t.T: '[1]BACOLOD RENTAL RATES'!#REF!
Name Crane5t.T: '[1]BACOLOD RENTAL RATES'!#REF!
Name Crane60t.T: '[1]BACOLOD RENTAL RATES'!#REF!
Name Cutter50.T: '[1]BACOLOD RENTAL RATES'!#REF!
Name Dcap: [3]Cons!$C$24
Name Drill115.T: '[1]BACOLOD RENTAL RATES'!#REF!
Name DT10m3.T: '[1]BACOLOD RENTAL RATES'!#REF!
Name DT5m3.T: '[1]BACOLOD RENTAL RATES'!#REF!
Name DT8m3.T: '[1]BACOLOD RENTAL RATES'!#REF!
Name DTHrate: [3]Cons!$C$25
Name Gen300kw.T: '[1]BACOLOD RENTAL RATES'!#REF!
Name Gen600kw.T: '[1]BACOLOD RENTAL RATES'!#REF!
Name Gen75kw.T: '[1]BACOLOD RENTAL RATES'!#REF!
Name Grader125hp.T: '[1]BACOLOD RENTAL RATES'!#REF!
Name Grader135hp.T: '[1]BACOLOD RENTAL RATES'!#REF!
Name Hammer3700kg.T: '[1]BACOLOD RENTAL RATES'!#REF!
Name Hammer7500kg.T: '[1]BACOLOD RENTAL RATES'!#REF!
Name item101: [4]entry!$B$16
Name ITEM102: [4]entry!$B$17
Name item200: [4]entry!$B$18
Name jimmy: '[2]BACOLOD RENTAL RATES'!#REF!
Name JkHammer15kg.T: '[1]BACOLOD RENTAL RATES'!#REF!
Name Loader.76m3.T: '[1]BACOLOD RENTAL RATES'!#REF!
Name Loader.83m3.T: '[1]BACOLOD RENTAL RATES'!#REF!
Name Loader.99m3.T: '[1]BACOLOD RENTAL RATES'!#REF!
Name Loader1.3m3.T: '[1]BACOLOD RENTAL RATES'!#REF!
Name Loader1.53m3.T: '[1]BACOLOD RENTAL RATES'!#REF!
Name Loader1.76m3.T: '[1]BACOLOD RENTAL RATES'!#REF!

Sheet SWA (July 6-9)
B1: STATEMENT OF WORK ACCOMPLISHMENT
E2: As of | F2: ='STEWA (July 6-9)'!I9 -> 46211
A4: Project Title: | B4: ='STEWA (July 6-9)'!I12 -> CONSTRUCTION OF BOX CULVERT ALONG CATO-CONNER ROAD, TUAO
A5: Location: | B5: ='STEWA (July 6-9)'!I13 -> Cato, Tuao, Cagayan
R6: Feb 2-6, 2026 | S6: Feb. 9-13, 2026 | T6: Feb. 16-20, 2026 | U6: Feb 23-27, 2026
A7: ITEM | B7: DESCRIPTION OF WORK | D7: PROGRAMMED | F7: UNIT | G7: CONTRACT | H7: WEIGHT | I7: ACCOMPLISHMENT | L7: WEIGHT | M7: REMARKS/
A8: NO. | D8: QUANTITY | F8: PRICE | G8: AMOUNT | H8: % | I8: PREVIOUS | J8: THIS PERIOD | K8: TO DATE | L8: % | M8: STATUS
D9: ORIGINAL
A10: I | B10: OTHER GENERAL REQUIREMENTS
A11: B.5 | B11: Project Billboard | D11: 2 | E11: Each | F11: 6195 | G11: =F11*D11 -> 12390 | H11: =ROUND((G11/$G$34),5) -> 0.00415 | J11: =K11-I11 -> 0 | K11: 0 | L11: =ROUND(K11/$G$34,5) -> 0 | M11: =IF(L11=H11,"COMPLETED",IF(L11=0,"Not Yet Started","On going")) -> Not Yet Started | N11: =(J11/G11)*D11 -> 0 | P11: =H11-L11 -> 0.00415
A12: B.7 | B12: Construction Safety and Health Program | D12: 1 | E12: L.S. | F12: 15561 | G12: =F12*D12 -> 15561 | H12: =ROUND((G12/$G$34),5) -> 0.00521 | J12: =K12-I12 -> 7780.5 | K12: =D12/2*F12 -> 7780.5 | L12: =ROUND(K12/$G$34,5) -> 0.0026 | M12: =IF(L12=H12,"COMPLETED",IF(L12=0,"Not Yet Started","On going")) -> On going | N12: =(J12/G12)*D12 -> 0.5 | P12: =H12-L12 -> 0.00261
A13: B.9 | B13: Mobilization/ Demobilization | D13: 1 | E13: L.S. | F13: 29488.2 | G13: =F13*D13 -> 29488.2 | H13: =ROUND((G13/$G$34),5) -> 0.00987 | J13: =K13-I13 -> 14744.1 | K13: =D13/2*F13 -> 14744.1 | L13: =ROUND(K13/$G$34,5) -> 0.00494 | M13: =IF(L13=H13,"COMPLETED",IF(L13=0,"Not Yet Started","On going")) -> On going | N13: =(J13/G13)*D13 -> 0.5 | P13: =H13-L13 -> 0.00493
A14: II. | B14: WORK ITEMS
A15: 101(3)b1 | B15: Removal of Actual Structures/Obstructions (ACP) | D15: 88.45 | E15: sq.m | F15: 582.35 | G15: =F15*D15 -> 51508.858 | H15: =ROUND((G15/$G$34),5) -> 0.01724 | J15: =K15-I15 -> 25754.429 | K15: =D15/2*F15 -> 25754.429 | L15: =ROUND(K15/$G$34,5) -> 0.00862 | M15: =IF(L15=H15,"COMPLETED",IF(L15=0,"Not Yet Started","On going")) -> On going | N15: =(J15/G15)*D15 -> 44.225 | P15: =H15-L15 -> 0.00862
A16: 101(6) | B16: Removal of Structures and Obstruction | D16: 40.85 | E16: cu.m | F16: 673.88 | G16: =F16*D16 -> 27527.998 | H16: =ROUND((G16/$G$34),5) -> 0.00921 | J16: =K16-I16 -> 0 | L16: =ROUND(K16/$G$34,5) -> 0 | M16: =IF(L16=H16,"COMPLETED",IF(L16=0,"Not Yet Started","On going")) -> Not Yet Started | N16: =(J16/G16)*D16 -> 0 | P16: =H16-L16 -> 0.00921
A17: 103(1)a | B17: Structure Excavation (Common Soil) | D17: 36.25 | E17: cu.m | F17: 462.81 | G17: =F17*D17 -> 16776.862 | H17: =ROUND((G17/$G$34),5) -> 0.00562 | J17: =K17-I17 -> 16776.862 | K17: =D17*F17 -> 16776.862 | L17: =ROUND(K17/$G$34,5) -> 0.00562 | M17: =IF(L17=H17,"COMPLETED",IF(L17=0,"Not Yet Started","On going")) -> COMPLETED | N17: =(J17/G17)*D17 -> 36.25 | P17: =H17-L17 -> 0
A18: 105(1) | B18: Sub-Grade Preparation (Common Materials) | D18: 166.05 | E18: sq.m | F18: 142.63 | G18: =F18*D18 -> 23683.712 | H18: =ROUND((G18/$G$34),5) -> 0.00793 | J18: =K18-I18 -> 11841.856 | K18: =D18/2*F18 -> 11841.856 | L18: =ROUND(K18/$G$34,5) -> 0.00396 | M18: =IF(L18=H18,"COMPLETED",IF(L18=0,"Not Yet Started","On going")) -> On going | N18: =(J18/G18)*D18 -> 83.025 | P18: =H18-L18 -> 0.00397
A19: III. | B19: SUB-BASE COURSE
A20: 200(1) | B20: Aggregates Sub-Base Course | D20: 42.64 | E20: cu.m | F20: 942.84 | G20: =F20*D20 -> 40202.698 | H20: =ROUND((G20/$G$34),5) -> 0.01346 | I20: 0 | J20: =K20-I20 -> 0 | L20: =ROUND(K20/$G$34,5) -> 0 | M20: =IF(L20=H20,"COMPLETED",IF(L20=0,"Not Yet Started","On going")) -> Not Yet Started | N20: =(J20/G20)*D20 -> 0 | P20: =H20-L20 -> 0.01346
A21: IV. | B21: SURFACE COURSE
A22: 311(1)c | B22: Portland Cement Concrete Pavement , 230mm thick (Unreinforced) | D22: 125.05 | E22: sq.m | F22: 2614.56 | G22: =F22*D22 -> 326950.73 | H22: =ROUND((G22/$G$34),5) -> 0.10944 | J22: =K22-I22 -> 0 | L22: =ROUND(K22/$G$34,5) -> 0 | M22: =IF(L22=H22,"COMPLETED",IF(L22=0,"Not Yet Started","On going")) -> Not Yet Started
A23: 311(2)e1 | B23: Portland Cement Concrete Pavement (reinforced) | D23: 49.07 | E23: sq.m | F23: 2792.47 | G23: =F23*D23 -> 137026.5 | H23: =ROUND((G23/$G$34),5) -> 0.04587 | J23: =K23-I23 -> 0 | L23: =ROUND(K23/$G$34,5) -> 0 | M23: =IF(L23=H23,"COMPLETED",IF(L23=0,"Not Yet Started","On going")) -> Not Yet Started
A24: V. | B24: DRAINAGE AND SLOPE PROTECTION
A25: a. | B25: RETAINING WALL | N25: =(J25/G25)*D25 -> #DIV/0! | P25: =H25-L25 -> 0
A26: 404(1)a | B26: Reiinforced Steel, Grade 40 (Retaining Wall) | D26: 1499.3 | E26: kgs | F26: 119.31 | G26: =F26*D26 -> 178881.48 | H26: =ROUND((G26/$G$34),5) -> 0.05988 | J26: =K26-I26 -> 0 | L26: =ROUND(K26/$G$34,5) -> 0 | M26: =IF(L26=H26,"COMPLETED",IF(L26=0,"Not Yet Started","On going")) -> Not Yet Started | N26: =(J26/G26)*D26 -> 0 | P26: =H26-L26 -> 0.05988
A27: 404(1)b | B27: Reiinforced Steel, Grade 60 (Retaining Wall) | D27: 1665.38 | E27: kgs | F27: 128.04 | G27: =F27*D27 -> 213235.26 | H27: =ROUND((G27/$G$34),5) -> 0.07138 | L27: =ROUND(K27/$G$34,5) -> 0 | M27: =IF(L27=H27,"COMPLETED",IF(L27=0,"Not Yet Started","On going")) -> Not Yet Started
A28: 405(1)a3 | B28: Structural Concrete Class A (Retaining Wall) | D28: 71.29 | E28: cu.m | F28: 5927.8 | G28: =F28*D28 -> 422592.86 | H28: =ROUND((G28/$G$34),5) -> 0.14146 | J28: =K28-I28 -> 0 | K28: 0 | L28: =ROUND(K28/$G$34,5) -> 0 | M28: =IF(L28=H28,"COMPLETED",IF(L28=0,"Not Yet Started","On going")) -> Not Yet Started | N28: =(J28/G28)*D28 -> 0 | P28: =H28-L28 -> 0.14146
A29: b. | B29: REINFORCED CONCRETE BOX CULVERT | N29: =(J29/G29)*D29 -> #DIV/0! | P29: =H29-L29 -> 0
A30: 404(1)a | B30: Reinforced Steel, Grade 40 (RCBC Double Barrel) | D30: 4406.33 | E30: kgs | F30: 109.59 | G30: =F30*D30 -> 482889.7 | H30: =ROUND((G30/$G$34),5) -> 0.16164 | J30: =K30-I30 -> 0 | L30: =ROUND(K30/$G$34,5) -> 0 | M30: =IF(L30=H30,"COMPLETED",IF(L30=0,"Not Yet Started","On going")) -> Not Yet Started
A31: 404(1)b | B31: Reinforced Steel, Grade 60 (RCBC Double Barrel) | D31: 3045.99 | E31: kgs | F31: 125.23 | G31: =F31*D31 -> 381449.33 | H31: =ROUND((G31/$G$34),5) -> 0.12768 | J31: =K31-I31 -> 0 | L31: =ROUND(K31/$G$34,5) -> 0 | M31: =IF(L31=H31,"COMPLETED",IF(L31=0,"Not Yet Started","On going")) -> Not Yet Started
A32: 404(1)c | B32: Structural Concrete Class A (RCBC Double Barrel) | D32: 101.82 | E32: cu.m | F32: 6160.48 | G32: =F32*D32 -> 627260.07 | H32: =ROUND((G32/$G$34),5) -> 0.20997 | J32: =K32-I32 -> 0 | L32: =ROUND(K32/$G$34,5) -> 0 | M32: =IF(L32=H32,"COMPLETED",IF(L32=0,"Not Yet Started","On going")) -> Not Yet Started
A34: T O T A L S | G34: =SUM(G10:G32) -> 2987425.3 | H34: =SUM(H10:H36) -> 1.00002 | J34: =SUM(J10:J33) -> 76897.747 | K34: =SUM(K10:K33) -> 76897.747 | L34: =SUM(L10:L32) -> 0.02574 | N34: BOQ
F37: % THIS ACCOMPLISHMENT | I37: =L34 -> 0.02574
F38: TOTAL PROJECT COST | I38: =G34 -> 2987425.3
F39: TOTAL THIS ACCOMPLISHMENT | I39: =J34 -> 76897.747
E40: Less: | F40: MOBILIZATION
F41: TOTAL THIS VOUCHER | I41: =SUM(J34-I40) -> 76897.747
A44: Prepared by: | C44: Checked by: | G44: Recommending Approval: | K44: Approved:
P45: =H33-L33 -> 0
P46: =SUM(P11:P45) -> 0.24829
...

Sheet STEWA (July 6-9)
A2: Republic of the Philippines
A3: PROVINCE OF CAGAYAN
A4: Capitol Hills, Tuguegarao City
A5: PROVINCIAL ENGINEER'S OFFICE
H6: JUST FILL IN ON BLUE CELL!!! | M6: LEGEND:
A7: STATEMENT OF TIME ELAPSED AND WORK ACCOMPLISHED | M7: single | N7: WITHOUT REVISION
M8: in a relationship | N8: WITH REVISION
B9: =I9 -> 46211 | H9: To be Filled In | I9: 46211 | M9: complicated | N9: ON THE EXPIRY DATE WITHOUT REVISION
M10: married | N10: ON THE EXPIRY DATE WITH REVISION
M11: separated | N11: ON THE COMPLETION DATE WITHOUT REVISION
A12: Project Name | C12: : | D12: =I12 -> CONSTRUCTION OF BOX CULVERT ALONG CATO-CONNER ROAD, TUAO | H12: To be Filled In | I12: CONSTRUCTION OF BOX CULVERT ALONG CATO-CONNER ROAD, TUAO | J12: Project Name | M12: divorced | N12: ON THE COMPLETION DATE WITH REVISION
A13: Location | C13: : | D13: =I13 -> Cato, Tuao, Cagayan | H13: To be Filled In | I13: Cato, Tuao, Cagayan | J13: Location | M13: LDR_1 | N13: WITHOUT REVISION
A14: Contract Amount | C14: : | D14: =I14 -> 3000000 | H14: To be Filled In | I14: 3000000 | J14: Contract Amount | M14: LDR_2 | N14: WITH REVISION
A15: Contractor | C15: : | D15: =I15 -> Dragonace Construction Corporation | H15: To be Filled In | I15: Dragonace Construction Corporation | J15: Contractor
A17: 1. | B17: Period Covered: | C17: : | D17: =D20+9 -> 46026 | E17: to
D18: =+B9 -> 46211
A19: 2. | B19: Contract Duration | C19: : | D19: 95 | H19: To be Filled In | I19: 95 | J19: Contract Duration | M19: 45659 | O19: 46030
A20: 3. | B20: Date of Receipt of Notice to Proceed | C20: : | D20: =I20 -> 46017 | H20: To be Filled In | I20: 46017 | J20: Date of Receipt of Notice to Proceed | M20: =M19-D17 -> -367 | O20: 46209
A21: 4. | B21: Expiry Date | C21: : | D21: =+D17+D19 -> 46121 | O21: =O20-O19 -> 179
A22: 5. | B22: Approved Time Extension | C22: : | H22: To be Filled In | J22: Approved Time Extension
A23: 6. | B23: Approved Time Suspension | C23: : | D23: =I23 -> 179 | H23: To be Filled In | I23: 179 | J23: Approved Time Suspension
A24: 7. | B24: Total Time Extension | H24: Don't Fill In | I24: =D22 -> 0 | J24: Total Time Extension
A25: 8. | B25: Revised Contract Duration | C25: : | D25: =IF(I24>0,I25,0) -> 0 | H25: Don't Fill In | I25: =IF(D22>0,D22+I19,0) -> 0 | J25: Revised Contract Duration
A26: 9. | B26: Revised Expiry Date | C26: : | D26: =D21+D23+D22 -> 46300 | I26: =I22+I23 -> 179
A27: 10. | B27: Total Calendar days Elapsed to Date | C27: : | D27: =+D18-D17+1-D23 -> 7
A28: 11. | B28: Percentage of work accomplished - Actual | C28: : | D28: ='SWA (July 6-9)'!L34 -> 0.02574 | J28: (FROM SWA)
A29: 12. | B29: Percentage of work accomplished -Planned | C29: : | D29: =I29 -> 0.013336701 | H29: Don't Fill In | I29: =(((SIN((((180*((D27))/D19)-90)*(3.14159265358979/180)))+1)*50)/100) -> 0.013336701 | J29: W/ FORMULA - Planned (WITHOUT time extension)
A30: 13. | B30: Slippage | C30: : | D30: =D28-D29 -> 0.012403299 | H30: Don't Fill In | I30: =IF(I25>0,(((SIN((((180*((D27))/D25)-90)*(3.14159265358979/180)))+1)*50)/100),"") | J30: W/ FORMULA - Planned (WITH time extension)
A31: 14. | B31: Remarks | C31: : | D31: ONGOING
H32: Don't Fill In | I32: =D27/D19 -> 0.073684211 | J32: LINEAR - Planned (WITHOUT time extension)
H33: Don't Fill In | I33: 1 | J33: LINEAR - Planned (WITH time extension)
B36: Submitted by: | D36: Noted by: | H36: F | I36: WRITE "F" - OPT TO USE FORMULA
I37: WRITE "L" - OPT TO USE LINEAR
B39: PORFIRIO S. CANAPI | D39: KATHLEEN MEI P. BAGASIN
B40: Engineer II | D40: Engineer IV (Chief-Construction Division)
B50: EMAIL: peo@cagayan.gov.ph

Sheet SWA (July 13-17)
B1: STATEMENT OF WORK ACCOMPLISHMENT
E2: As of | F2: ='STEWA (July 13-17)'!I9 -> 46220
A4: Project Title: | B4: ='STEWA (July 6-9)'!I12 -> CONSTRUCTION OF BOX CULVERT ALONG CATO-CONNER ROAD, TUAO
A5: Location: | B5: ='STEWA (July 6-9)'!I13 -> Cato, Tuao, Cagayan
R6: Feb 2-6, 2026 | S6: Feb. 9-13, 2026 | T6: Feb. 16-20, 2026 | U6: Feb 23-27, 2026
A7: ITEM | B7: DESCRIPTION OF WORK | D7: PROGRAMMED | F7: UNIT | G7: CONTRACT | H7: WEIGHT | I7: ACCOMPLISHMENT | L7: WEIGHT | M7: REMARKS/
A8: NO. | D8: QUANTITY | F8: PRICE | G8: AMOUNT | H8: % | I8: PREVIOUS | J8: THIS PERIOD | K8: TO DATE | L8: % | M8: STATUS
D9: ORIGINAL
A10: I | B10: OTHER GENERAL REQUIREMENTS
A11: B.5 | B11: Project Billboard | D11: 2 | E11: Each | F11: 6195 | G11: =F11*D11 -> 12390 | H11: =ROUND((G11/$G$34),5) -> 0.00415 | J11: =K11-I11 -> 0 | K11: 0 | L11: =ROUND(K11/$G$34,5) -> 0 | M11: =IF(L11=H11,"COMPLETED",IF(L11=0,"Not Yet Started","On going")) -> Not Yet Started | N11: =(J11/G11)*D11 -> 0 | P11: =H11-L11 -> 0.00415
A12: B.7 | B12: Construction Safety and Health Program | D12: 1 | E12: L.S. | F12: 15561 | G12: =F12*D12 -> 15561 | H12: =ROUND((G12/$G$34),5) -> 0.00521 | J12: =K12-I12 -> 7780.5 | K12: =D12/2*F12 -> 7780.5 | L12: =ROUND(K12/$G$34,5) -> 0.0026 | M12: =IF(L12=H12,"COMPLETED",IF(L12=0,"Not Yet Started","On going")) -> On going | N12: =(J12/G12)*D12 -> 0.5 | P12: =H12-L12 -> 0.00261
A13: B.9 | B13: Mobilization/ Demobilization | D13: 1 | E13: L.S. | F13: 29488.2 | G13: =F13*D13 -> 29488.2 | H13: =ROUND((G13/$G$34),5) -> 0.00987 | J13: =K13-I13 -> 14744.1 | K13: =D13/2*F13 -> 14744.1 | L13: =ROUND(K13/$G$34,5) -> 0.00494 | M13: =IF(L13=H13,"COMPLETED",IF(L13=0,"Not Yet Started","On going")) -> On going | N13: =(J13/G13)*D13 -> 0.5 | P13: =H13-L13 -> 0.00493
A14: II. | B14: WORK ITEMS
A15: 101(3)b1 | B15: Removal of Actual Structures/Obstructions (ACP) | D15: 88.45 | E15: sq.m | F15: 582.35 | G15: =F15*D15 -> 51508.858 | H15: =ROUND((G15/$G$34),5) -> 0.01724 | J15: =K15-I15 -> 51508.858 | K15: =G15 -> 51508.858 | L15: =ROUND(K15/$G$34,5) -> 0.01724 | M15: =IF(L15=H15,"COMPLETED",IF(L15=0,"Not Yet Started","On going")) -> COMPLETED | N15: =(J15/G15)*D15 -> 88.45 | P15: =H15-L15 -> 0
A16: 101(6) | B16: Removal of Structures and Obstruction | D16: 40.85 | E16: cu.m | F16: 673.88 | G16: =F16*D16 -> 27527.998 | H16: =ROUND((G16/$G$34),5) -> 0.00921 | J16: =K16-I16 -> 0 | L16: =ROUND(K16/$G$34,5) -> 0 | M16: =IF(L16=H16,"COMPLETED",IF(L16=0,"Not Yet Started","On going")) -> Not Yet Started | N16: =(J16/G16)*D16 -> 0 | P16: =H16-L16 -> 0.00921
A17: 103(1)a | B17: Structure Excavation (Common Soil) | D17: 36.25 | E17: cu.m | F17: 462.81 | G17: =F17*D17 -> 16776.862 | H17: =ROUND((G17/$G$34),5) -> 0.00562 | J17: =K17-I17 -> 16776.862 | K17: =D17*F17 -> 16776.862 | L17: =ROUND(K17/$G$34,5) -> 0.00562 | M17: =IF(L17=H17,"COMPLETED",IF(L17=0,"Not Yet Started","On going")) -> COMPLETED | N17: =(J17/G17)*D17 -> 36.25 | P17: =H17-L17 -> 0
A18: 105(1) | B18: Sub-Grade Preparation (Common Materials) | D18: 166.05 | E18: sq.m | F18: 142.63 | G18: =F18*D18 -> 23683.712 | H18: =ROUND((G18/$G$34),5) -> 0.00793 | J18: =K18-I18 -> 11841.856 | K18: =D18/2*F18 -> 11841.856 | L18: =ROUND(K18/$G$34,5) -> 0.00396 | M18: =IF(L18=H18,"COMPLETED",IF(L18=0,"Not Yet Started","On going")) -> On going | N18: =(J18/G18)*D18 -> 83.025 | P18: =H18-L18 -> 0.00397
A19: III. | B19: SUB-BASE COURSE
A20: 200(1) | B20: Aggregates Sub-Base Course | D20: 42.64 | E20: cu.m | F20: 942.84 | G20: =F20*D20 -> 40202.698 | H20: =ROUND((G20/$G$34),5) -> 0.01346 | I20: 0 | J20: =K20-I20 -> 0 | L20: =ROUND(K20/$G$34,5) -> 0 | M20: =IF(L20=H20,"COMPLETED",IF(L20=0,"Not Yet Started","On going")) -> Not Yet Started | N20: =(J20/G20)*D20 -> 0 | P20: =H20-L20 -> 0.01346
A21: IV. | B21: SURFACE COURSE
A22: 311(1)c | B22: Portland Cement Concrete Pavement , 230mm thick (Unreinforced) | D22: 125.05 | E22: sq.m | F22: 2614.56 | G22: =F22*D22 -> 326950.73 | H22: =ROUND((G22/$G$34),5) -> 0.10944 | J22: =K22-I22 -> 0 | L22: =ROUND(K22/$G$34,5) -> 0 | M22: =IF(L22=H22,"COMPLETED",IF(L22=0,"Not Yet Started","On going")) -> Not Yet Started
A23: 311(2)e1 | B23: Portland Cement Concrete Pavement (reinforced) | D23: 49.07 | E23: sq.m | F23: 2792.47 | G23: =F23*D23 -> 137026.5 | H23: =ROUND((G23/$G$34),5) -> 0.04587 | J23: =K23-I23 -> 0 | L23: =ROUND(K23/$G$34,5) -> 0 | M23: =IF(L23=H23,"COMPLETED",IF(L23=0,"Not Yet Started","On going")) -> Not Yet Started
A24: V. | B24: DRAINAGE AND SLOPE PROTECTION
A25: a. | B25: RETAINING WALL | N25: =(J25/G25)*D25 -> #DIV/0! | P25: =H25-L25 -> 0
A26: 404(1)a | B26: Reiinforced Steel, Grade 40 (Retaining Wall) | D26: 1499.3 | E26: kgs | F26: 119.31 | G26: =F26*D26 -> 178881.48 | H26: =ROUND((G26/$G$34),5) -> 0.05988 | J26: =K26-I26 -> 0 | L26: =ROUND(K26/$G$34,5) -> 0 | M26: =IF(L26=H26,"COMPLETED",IF(L26=0,"Not Yet Started","On going")) -> Not Yet Started | N26: =(J26/G26)*D26 -> 0 | P26: =H26-L26 -> 0.05988
A27: 404(1)b | B27: Reiinforced Steel, Grade 60 (Retaining Wall) | D27: 1665.38 | E27: kgs | F27: 128.04 | G27: =F27*D27 -> 213235.26 | H27: =ROUND((G27/$G$34),5) -> 0.07138 | L27: =ROUND(K27/$G$34,5) -> 0 | M27: =IF(L27=H27,"COMPLETED",IF(L27=0,"Not Yet Started","On going")) -> Not Yet Started
A28: 405(1)a3 | B28: Structural Concrete Class A (Retaining Wall) | D28: 71.29 | E28: cu.m | F28: 5927.8 | G28: =F28*D28 -> 422592.86 | H28: =ROUND((G28/$G$34),5) -> 0.14146 | J28: =K28-I28 -> 0 | K28: 0 | L28: =ROUND(K28/$G$34,5) -> 0 | M28: =IF(L28=H28,"COMPLETED",IF(L28=0,"Not Yet Started","On going")) -> Not Yet Started | N28: =(J28/G28)*D28 -> 0 | P28: =H28-L28 -> 0.14146
A29: b. | B29: REINFORCED CONCRETE BOX CULVERT | N29: =(J29/G29)*D29 -> #DIV/0! | P29: =H29-L29 -> 0
A30: 404(1)a | B30: Reinforced Steel, Grade 40 (RCBC Double Barrel) | D30: 4406.33 | E30: kgs | F30: 109.59 | G30: =F30*D30 -> 482889.7 | H30: =ROUND((G30/$G$34),5) -> 0.16164 | J30: =K30-I30 -> 386311.76 | K30: =D30*0.8*F30 -> 386311.76 | L30: =ROUND(K30/$G$34,5) -> 0.12931 | M30: =IF(L30=H30,"COMPLETED",IF(L30=0,"Not Yet Started","On going")) -> On going
A31: 404(1)b | B31: Reinforced Steel, Grade 60 (RCBC Double Barrel) | D31: 3045.99 | E31: kgs | F31: 125.23 | G31: =F31*D31 -> 381449.33 | H31: =ROUND((G31/$G$34),5) -> 0.12768 | J31: =K31-I31 -> 305159.46 | K31: =D31*0.8*F31 -> 305159.46 | L31: =ROUND(K31/$G$34,5) -> 0.10215 | M31: =IF(L31=H31,"COMPLETED",IF(L31=0,"Not Yet Started","On going")) -> On going
A32: 404(1)c | B32: Structural Concrete Class A (RCBC Double Barrel) | D32: 101.82 | E32: cu.m | F32: 6160.48 | G32: =F32*D32 -> 627260.07 | H32: =ROUND((G32/$G$34),5) -> 0.20997 | J32: =K32-I32 -> 501808.06 | K32: =D32*0.8*F32 -> 501808.06 | L32: =ROUND(K32/$G$34,5) -> 0.16797 | M32: =IF(L32=H32,"COMPLETED",IF(L32=0,"Not Yet Started","On going")) -> On going
A34: T O T A L S | G34: =SUM(G10:G32) -> 2987425.3 | H34: =SUM(H10:H36) -> 1.00002 | J34: =SUM(J10:J33) -> 1295931.5 | K34: =SUM(K10:K33) -> 1295931.5 | L34: =SUM(L10:L32) -> 0.43379 | N34: BOQ
F37: % THIS ACCOMPLISHMENT | I37: =L34 -> 0.43379
F38: TOTAL PROJECT COST | I38: =G34 -> 2987425.3
F39: TOTAL THIS ACCOMPLISHMENT | I39: =J34 -> 1295931.5
E40: Less: | F40: MOBILIZATION
F41: TOTAL THIS VOUCHER | I41: =SUM(J34-I40) -> 1295931.5
A44: Prepared by: | C44: Checked by: | G44: Recommending Approval: | K44: Approved:
P45: =H33-L33 -> 0
P46: =SUM(P11:P45) -> 0.23967
...

Sheet STEWA (July 13-17)
A2: Republic of the Philippines
A3: PROVINCE OF CAGAYAN
A4: Capitol Hills, Tuguegarao City
A5: PROVINCIAL ENGINEER'S OFFICE
H6: JUST FILL IN ON BLUE CELL!!! | M6: LEGEND:
A7: STATEMENT OF TIME ELAPSED AND WORK ACCOMPLISHED | M7: single | N7: WITHOUT REVISION
M8: in a relationship | N8: WITH REVISION
B9: =I9 -> 46220 | H9: To be Filled In | I9: 46220 | M9: complicated | N9: ON THE EXPIRY DATE WITHOUT REVISION
M10: married | N10: ON THE EXPIRY DATE WITH REVISION
M11: separated | N11: ON THE COMPLETION DATE WITHOUT REVISION
A12: Project Name | C12: : | D12: =I12 -> CONSTRUCTION OF BOX CULVERT ALONG CATO-CONNER ROAD, TUAO | H12: To be Filled In | I12: CONSTRUCTION OF BOX CULVERT ALONG CATO-CONNER ROAD, TUAO | J12: Project Name | M12: divorced | N12: ON THE COMPLETION DATE WITH REVISION
A13: Location | C13: : | D13: =I13 -> Cato, Tuao, Cagayan | H13: To be Filled In | I13: Cato, Tuao, Cagayan | J13: Location | M13: LDR_1 | N13: WITHOUT REVISION
A14: Contract Amount | C14: : | D14: =I14 -> 3000000 | H14: To be Filled In | I14: 3000000 | J14: Contract Amount | M14: LDR_2 | N14: WITH REVISION
A15: Contractor | C15: : | D15: =I15 -> Dragonace Construction Corporation | H15: To be Filled In | I15: Dragonace Construction Corporation | J15: Contractor
A17: 1. | B17: Period Covered: | C17: : | D17: =D20+9 -> 46026 | E17: to
D18: =+B9 -> 46220
A19: 2. | B19: Contract Duration | C19: : | D19: 95 | H19: To be Filled In | I19: 95 | J19: Contract Duration | M19: 45659 | O19: 46030
A20: 3. | B20: Date of Receipt of Notice to Proceed | C20: : | D20: =I20 -> 46017 | H20: To be Filled In | I20: 46017 | J20: Date of Receipt of Notice to Proceed | M20: =M19-D17 -> -367 | O20: 46209
A21: 4. | B21: Expiry Date | C21: : | D21: =+D17+D19 -> 46121 | O21: =O20-O19 -> 179
A22: 5. | B22: Approved Time Extension | C22: : | H22: To be Filled In | J22: Approved Time Extension
A23: 6. | B23: Approved Time Suspension | C23: : | D23: =I23 -> 179 | H23: To be Filled In | I23: 179 | J23: Approved Time Suspension
A24: 7. | B24: Total Time Extension | H24: Don't Fill In | I24: =D22 -> 0 | J24: Total Time Extension
A25: 8. | B25: Revised Contract Duration | C25: : | D25: =IF(I24>0,I25,0) -> 0 | H25: Don't Fill In | I25: =IF(D22>0,D22+I19,0) -> 0 | J25: Revised Contract Duration
A26: 9. | B26: Revised Expiry Date | C26: : | D26: =D21+D23+D22 -> 46300 | I26: =I22+I23 -> 179
A27: 10. | B27: Total Calendar days Elapsed to Date | C27: : | D27: =+D18-D17+1-D23 -> 16
A28: 11. | B28: Percentage of work accomplished - Actual | C28: : | D28: ='SWA (July 13-17)'!L34 -> 0.43379 | J28: (FROM SWA)
A29: 12. | B29: Percentage of work accomplished -Planned | C29: : | D29: =I29 -> 0.06837176 | H29: Don't Fill In | I29: =(((SIN((((180*((D27))/D19)-90)*(3.14159265358979/180)))+1)*50)/100) -> 0.06837176 | J29: W/ FORMULA - Planned (WITHOUT time extension)
A30: 13. | B30: Slippage | C30: : | D30: =D28-D29 -> 0.36541824 | H30: Don't Fill In | I30: =IF(I25>0,(((SIN((((180*((D27))/D25)-90)*(3.14159265358979/180)))+1)*50)/100),"") | J30: W/ FORMULA - Planned (WITH time extension)
A31: 14. | B31: Remarks | C31: : | D31: ONGOING
H32: Don't Fill In | I32: =D27/D19 -> 0.16842105 | J32: LINEAR - Planned (WITHOUT time extension)
H33: Don't Fill In | I33: 1 | J33: LINEAR - Planned (WITH time extension)
B36: Submitted by: | D36: Noted by: | H36: F | I36: WRITE "F" - OPT TO USE FORMULA
I37: WRITE "L" - OPT TO USE LINEAR
B39: PORFIRIO S. CANAPI | D39: KATHLEEN MEI P. BAGASIN
B40: Engineer II | D40: Engineer IV (Chief-Construction Division)
B50: EMAIL: peo@cagayan.gov.ph

Sheet SWA (July 20-24)
B1: STATEMENT OF WORK ACCOMPLISHMENT
E2: As of | F2: ='STEWA (July 13-17)'!I9 -> 46220
A4: Project Title: | B4: ='STEWA (July 6-9)'!I12 -> CONSTRUCTION OF BOX CULVERT ALONG CATO-CONNER ROAD, TUAO
A5: Location: | B5: ='STEWA (July 6-9)'!I13 -> Cato, Tuao, Cagayan
R6: Feb 2-6, 2026 | S6: Feb. 9-13, 2026 | T6: Feb. 16-20, 2026 | U6: Feb 23-27, 2026
A7: ITEM | B7: DESCRIPTION OF WORK | D7: PROGRAMMED | F7: UNIT | G7: CONTRACT | H7: WEIGHT | I7: ACCOMPLISHMENT | L7: WEIGHT | M7: REMARKS/
A8: NO. | D8: QUANTITY | F8: PRICE | G8: AMOUNT | H8: % | I8: PREVIOUS | J8: THIS PERIOD | K8: TO DATE | L8: % | M8: STATUS
D9: ORIGINAL
A10: I | B10: OTHER GENERAL REQUIREMENTS
A11: B.5 | B11: Project Billboard | D11: 2 | E11: Each | F11: 6195 | G11: =F11*D11 -> 12390 | H11: =ROUND((G11/$G$34),5) -> 0.00415 | J11: =K11-I11 -> 0 | K11: 0 | L11: =ROUND(K11/$G$34,5) -> 0 | M11: =IF(L11=H11,"COMPLETED",IF(L11=0,"Not Yet Started","On going")) -> Not Yet Started | N11: =(J11/G11)*D11 -> 0 | P11: =H11-L11 -> 0.00415
A12: B.7 | B12: Construction Safety and Health Program | D12: 1 | E12: L.S. | F12: 15561 | G12: =F12*D12 -> 15561 | H12: =ROUND((G12/$G$34),5) -> 0.00521 | J12: =K12-I12 -> 7780.5 | K12: =D12/2*F12 -> 7780.5 | L12: =ROUND(K12/$G$34,5) -> 0.0026 | M12: =IF(L12=H12,"COMPLETED",IF(L12=0,"Not Yet Started","On going")) -> On going | N12: =(J12/G12)*D12 -> 0.5 | P12: =H12-L12 -> 0.00261
A13: B.9 | B13: Mobilization/ Demobilization | D13: 1 | E13: L.S. | F13: 29488.2 | G13: =F13*D13 -> 29488.2 | H13: =ROUND((G13/$G$34),5) -> 0.00987 | J13: =K13-I13 -> 14744.1 | K13: =D13/2*F13 -> 14744.1 | L13: =ROUND(K13/$G$34,5) -> 0.00494 | M13: =IF(L13=H13,"COMPLETED",IF(L13=0,"Not Yet Started","On going")) -> On going | N13: =(J13/G13)*D13 -> 0.5 | P13: =H13-L13 -> 0.00493
A14: II. | B14: WORK ITEMS
A15: 101(3)b1 | B15: Removal of Actual Structures/Obstructions (ACP) | D15: 88.45 | E15: sq.m | F15: 582.35 | G15: =F15*D15 -> 51508.858 | H15: =ROUND((G15/$G$34),5) -> 0.01724 | J15: =K15-I15 -> 51508.858 | K15: =G15 -> 51508.858 | L15: =ROUND(K15/$G$34,5) -> 0.01724 | M15: =IF(L15=H15,"COMPLETED",IF(L15=0,"Not Yet Started","On going")) -> COMPLETED | N15: =(J15/G15)*D15 -> 88.45 | P15: =H15-L15 -> 0
A16: 101(6) | B16: Removal of Structures and Obstruction | D16: 40.85 | E16: cu.m | F16: 673.88 | G16: =F16*D16 -> 27527.998 | H16: =ROUND((G16/$G$34),5) -> 0.00921 | J16: =K16-I16 -> 0 | L16: =ROUND(K16/$G$34,5) -> 0 | M16: =IF(L16=H16,"COMPLETED",IF(L16=0,"Not Yet Started","On going")) -> Not Yet Started | N16: =(J16/G16)*D16 -> 0 | P16: =H16-L16 -> 0.00921
A17: 103(1)a | B17: Structure Excavation (Common Soil) | D17: 36.25 | E17: cu.m | F17: 462.81 | G17: =F17*D17 -> 16776.862 | H17: =ROUND((G17/$G$34),5) -> 0.00562 | J17: =K17-I17 -> 16776.862 | K17: =D17*F17 -> 16776.862 | L17: =ROUND(K17/$G$34,5) -> 0.00562 | M17: =IF(L17=H17,"COMPLETED",IF(L17=0,"Not Yet Started","On going")) -> COMPLETED | N17: =(J17/G17)*D17 -> 36.25 | P17: =H17-L17 -> 0
A18: 105(1) | B18: Sub-Grade Preparation (Common Materials) | D18: 166.05 | E18: sq.m | F18: 142.63 | G18: =F18*D18 -> 23683.712 | H18: =ROUND((G18/$G$34),5) -> 0.00793 | J18: =K18-I18 -> 11841.856 | K18: =D18/2*F18 -> 11841.856 | L18: =ROUND(K18/$G$34,5) -> 0.00396 | M18: =IF(L18=H18,"COMPLETED",IF(L18=0,"Not Yet Started","On going")) -> On going | N18: =(J18/G18)*D18 -> 83.025 | P18: =H18-L18 -> 0.00397
A19: III. | B19: SUB-BASE COURSE
A20: 200(1) | B20: Aggregates Sub-Base Course | D20: 42.64 | E20: cu.m | F20: 942.84 | G20: =F20*D20 -> 40202.698 | H20: =ROUND((G20/$G$34),5) -> 0.01346 | I20: 0 | J20: =K20-I20 -> 0 | L20: =ROUND(K20/$G$34,5) -> 0 | M20: =IF(L20=H20,"COMPLETED",IF(L20=0,"Not Yet Started","On going")) -> Not Yet Started | N20: =(J20/G20)*D20 -> 0 | P20: =H20-L20 -> 0.01346
A21: IV. | B21: SURFACE COURSE
A22: 311(1)c | B22: Portland Cement Concrete Pavement , 230mm thick (Unreinforced) | D22: 125.05 | E22: sq.m | F22: 2614.56 | G22: =F22*D22 -> 326950.73 | H22: =ROUND((G22/$G$34),5) -> 0.10944 | J22: =K22-I22 -> 0 | L22: =ROUND(K22/$G$34,5) -> 0 | M22: =IF(L22=H22,"COMPLETED",IF(L22=0,"Not Yet Started","On going")) -> Not Yet Started
A23: 311(2)e1 | B23: Portland Cement Concrete Pavement (reinforced) | D23: 49.07 | E23: sq.m | F23: 2792.47 | G23: =F23*D23 -> 137026.5 | H23: =ROUND((G23/$G$34),5) -> 0.04587 | J23: =K23-I23 -> 0 | L23: =ROUND(K23/$G$34,5) -> 0 | M23: =IF(L23=H23,"COMPLETED",IF(L23=0,"Not Yet Started","On going")) -> Not Yet Started
A24: V. | B24: DRAINAGE AND SLOPE PROTECTION
A25: a. | B25: RETAINING WALL | N25: =(J25/G25)*D25 -> #DIV/0! | P25: =H25-L25 -> 0
A26: 404(1)a | B26: Reiinforced Steel, Grade 40 (Retaining Wall) | D26: 1499.3 | E26: kgs | F26: 119.31 | G26: =F26*D26 -> 178881.48 | H26: =ROUND((G26/$G$34),5) -> 0.05988 | J26: =K26-I26 -> 0 | L26: =ROUND(K26/$G$34,5) -> 0 | M26: =IF(L26=H26,"COMPLETED",IF(L26=0,"Not Yet Started","On going")) -> Not Yet Started | N26: =(J26/G26)*D26 -> 0 | P26: =H26-L26 -> 0.05988
A27: 404(1)b | B27: Reiinforced Steel, Grade 60 (Retaining Wall) | D27: 1665.38 | E27: kgs | F27: 128.04 | G27: =F27*D27 -> 213235.26 | H27: =ROUND((G27/$G$34),5) -> 0.07138 | L27: =ROUND(K27/$G$34,5) -> 0 | M27: =IF(L27=H27,"COMPLETED",IF(L27=0,"Not Yet Started","On going")) -> Not Yet Started
A28: 405(1)a3 | B28: Structural Concrete Class A (Retaining Wall) | D28: 71.29 | E28: cu.m | F28: 5927.8 | G28: =F28*D28 -> 422592.86 | H28: =ROUND((G28/$G$34),5) -> 0.14146 | J28: =K28-I28 -> 0 | K28: 0 | L28: =ROUND(K28/$G$34,5) -> 0 | M28: =IF(L28=H28,"COMPLETED",IF(L28=0,"Not Yet Started","On going")) -> Not Yet Started | N28: =(J28/G28)*D28 -> 0 | P28: =H28-L28 -> 0.14146
A29: b. | B29: REINFORCED CONCRETE BOX CULVERT | N29: =(J29/G29)*D29 -> #DIV/0! | P29: =H29-L29 -> 0
A30: 404(1)a | B30: Reinforced Steel, Grade 40 (RCBC Double Barrel) | D30: 4406.33 | E30: kgs | F30: 109.59 | G30: =F30*D30 -> 482889.7 | H30: =ROUND((G30/$G$34),5) -> 0.16164 | J30: =K30-I30 -> 482889.7 | K30: =G30 -> 482889.7 | L30: =ROUND(K30/$G$34,5) -> 0.16164 | M30: =IF(L30=H30,"COMPLETED",IF(L30=0,"Not Yet Started","On going")) -> COMPLETED
A31: 404(1)b | B31: Reinforced Steel, Grade 60 (RCBC Double Barrel) | D31: 3045.99 | E31: kgs | F31: 125.23 | G31: =F31*D31 -> 381449.33 | H31: =ROUND((G31/$G$34),5) -> 0.12768 | J31: =K31-I31 -> 381449.33 | K31: =G31 -> 381449.33 | L31: =ROUND(K31/$G$34,5) -> 0.12768 | M31: =IF(L31=H31,"COMPLETED",IF(L31=0,"Not Yet Started","On going")) -> COMPLETED
A32: 404(1)c | B32: Structural Concrete Class A (RCBC Double Barrel) | D32: 101.82 | E32: cu.m | F32: 6160.48 | G32: =F32*D32 -> 627260.07 | H32: =ROUND((G32/$G$34),5) -> 0.20997 | J32: =K32-I32 -> 627260.07 | K32: =G32 -> 627260.07 | L32: =ROUND(K32/$G$34,5) -> 0.20997 | M32: =IF(L32=H32,"COMPLETED",IF(L32=0,"Not Yet Started","On going")) -> COMPLETED
A34: T O T A L S | G34: =SUM(G10:G32) -> 2987425.3 | H34: =SUM(H10:H36) -> 1.00002 | J34: =SUM(J10:J33) -> 1594251.3 | K34: =SUM(K10:K33) -> 1594251.3 | L34: =SUM(L10:L32) -> 0.53365 | N34: BOQ
F37: % THIS ACCOMPLISHMENT | I37: =L34 -> 0.53365
F38: TOTAL PROJECT COST | I38: =G34 -> 2987425.3
F39: TOTAL THIS ACCOMPLISHMENT | I39: =J34 -> 1594251.3
E40: Less: | F40: MOBILIZATION
F41: TOTAL THIS VOUCHER | I41: =SUM(J34-I40) -> 1594251.3
A44: Prepared by: | C44: Checked by: | G44: Recommending Approval: | K44: Approved:
P45: =H33-L33 -> 0
P46: =SUM(P11:P45) -> 0.23967
...

Sheet STEWA (July 20-24)
A2: Republic of the Philippines
A3: PROVINCE OF CAGAYAN
A4: Capitol Hills, Tuguegarao City
A5: PROVINCIAL ENGINEER'S OFFICE
H6: JUST FILL IN ON BLUE CELL!!! | M6: LEGEND:
A7: STATEMENT OF TIME ELAPSED AND WORK ACCOMPLISHED | M7: single | N7: WITHOUT REVISION
M8: in a relationship | N8: WITH REVISION
B9: =I9 -> 46227 | H9: To be Filled In | I9: 46227 | M9: complicated | N9: ON THE EXPIRY DATE WITHOUT REVISION
M10: married | N10: ON THE EXPIRY DATE WITH REVISION
M11: separated | N11: ON THE COMPLETION DATE WITHOUT REVISION
A12: Project Name | C12: : | D12: =I12 -> CONSTRUCTION OF BOX CULVERT ALONG CATO-CONNER ROAD, TUAO | H12: To be Filled In | I12: CONSTRUCTION OF BOX CULVERT ALONG CATO-CONNER ROAD, TUAO | J12: Project Name | M12: divorced | N12: ON THE COMPLETION DATE WITH REVISION
A13: Location | C13: : | D13: =I13 -> Cato, Tuao, Cagayan | H13: To be Filled In | I13: Cato, Tuao, Cagayan | J13: Location | M13: LDR_1 | N13: WITHOUT REVISION
A14: Contract Amount | C14: : | D14: =I14 -> 3000000 | H14: To be Filled In | I14: 3000000 | J14: Contract Amount | M14: LDR_2 | N14: WITH REVISION
A15: Contractor | C15: : | D15: =I15 -> Dragonace Construction Corporation | H15: To be Filled In | I15: Dragonace Construction Corporation | J15: Contractor
A17: 1. | B17: Period Covered: | C17: : | D17: =D20+9 -> 46026 | E17: to
D18: =+B9 -> 46227
A19: 2. | B19: Contract Duration | C19: : | D19: 95 | H19: To be Filled In | I19: 95 | J19: Contract Duration | M19: 45659 | O19: 46030
A20: 3. | B20: Date of Receipt of Notice to Proceed | C20: : | D20: =I20 -> 46017 | H20: To be Filled In | I20: 46017 | J20: Date of Receipt of Notice to Proceed | M20: =M19-D17 -> -367 | O20: 46209
A21: 4. | B21: Expiry Date | C21: : | D21: =+D17+D19 -> 46121 | O21: =O20-O19 -> 179
A22: 5. | B22: Approved Time Extension | C22: : | H22: To be Filled In | J22: Approved Time Extension
A23: 6. | B23: Approved Time Suspension | C23: : | D23: =I23 -> 179 | H23: To be Filled In | I23: 179 | J23: Approved Time Suspension
A24: 7. | B24: Total Time Extension | H24: Don't Fill In | I24: =D22 -> 0 | J24: Total Time Extension
A25: 8. | B25: Revised Contract Duration | C25: : | D25: =IF(I24>0,I25,0) -> 0 | H25: Don't Fill In | I25: =IF(D22>0,D22+I19,0) -> 0 | J25: Revised Contract Duration
A26: 9. | B26: Revised Expiry Date | C26: : | D26: =D21+D23+D22 -> 46300 | I26: =I22+I23 -> 179
A27: 10. | B27: Total Calendar days Elapsed to Date | C27: : | D27: =+D18-D17+1-D23 -> 23
A28: 11. | B28: Percentage of work accomplished - Actual | C28: : | D28: ='SWA (July 13-17)'!L34 -> 0.43379 | J28: (FROM SWA)
A29: 12. | B29: Percentage of work accomplished -Planned | C29: : | D29: =I29 -> 0.1377874 | H29: Don't Fill In | I29: =(((SIN((((180*((D27))/D19)-90)*(3.14159265358979/180)))+1)*50)/100) -> 0.1377874 | J29: W/ FORMULA - Planned (WITHOUT time extension)
A30: 13. | B30: Slippage | C30: : | D30: =D28-D29 -> 0.2960026 | H30: Don't Fill In | I30: =IF(I25>0,(((SIN((((180*((D27))/D25)-90)*(3.14159265358979/180)))+1)*50)/100),"") | J30: W/ FORMULA - Planned (WITH time extension)
A31: 14. | B31: Remarks | C31: : | D31: ONGOING
H32: Don't Fill In | I32: =D27/D19 -> 0.24210526 | J32: LINEAR - Planned (WITHOUT time extension)
H33: Don't Fill In | I33: 1 | J33: LINEAR - Planned (WITH time extension)
B36: Submitted by: | D36: Noted by: | H36: F | I36: WRITE "F" - OPT TO USE FORMULA
I37: WRITE "L" - OPT TO USE LINEAR
B39: PORFIRIO S. CANAPI | D39: KATHLEEN MEI P. BAGASIN
B40: Engineer II | D40: Engineer IV (Chief-Construction Division)
B50: EMAIL: peo@cagayan.gov.ph

Sheet SWA (July 27-30)
B1: STATEMENT OF WORK ACCOMPLISHMENT
E2: As of | F2: ='STEWA (July 13-17)'!I9 -> 46220
A4: Project Title: | B4: ='STEWA (July 6-9)'!I12 -> CONSTRUCTION OF BOX CULVERT ALONG CATO-CONNER ROAD, TUAO
A5: Location: | B5: ='STEWA (July 6-9)'!I13 -> Cato, Tuao, Cagayan
R6: Feb 2-6, 2026 | S6: Feb. 9-13, 2026 | T6: Feb. 16-20, 2026 | U6: Feb 23-27, 2026
A7: ITEM | B7: DESCRIPTION OF WORK | D7: PROGRAMMED | F7: UNIT | G7: CONTRACT | H7: WEIGHT | I7: ACCOMPLISHMENT | L7: WEIGHT | M7: REMARKS/
A8: NO. | D8: QUANTITY | F8: PRICE | G8: AMOUNT | H8: % | I8: PREVIOUS | J8: THIS PERIOD | K8: TO DATE | L8: % | M8: STATUS
D9: ORIGINAL
A10: I | B10: OTHER GENERAL REQUIREMENTS
A11: B.5 | B11: Project Billboard | D11: 2 | E11: Each | F11: 6195 | G11: =F11*D11 -> 12390 | H11: =ROUND((G11/$G$34),5) -> 0.00415 | J11: =K11-I11 -> 0 | K11: 0 | L11: =ROUND(K11/$G$34,5) -> 0 | M11: =IF(L11=H11,"COMPLETED",IF(L11=0,"Not Yet Started","On going")) -> Not Yet Started | N11: =(J11/G11)*D11 -> 0 | P11: =H11-L11 -> 0.00415
A12: B.7 | B12: Construction Safety and Health Program | D12: 1 | E12: L.S. | F12: 15561 | G12: =F12*D12 -> 15561 | H12: =ROUND((G12/$G$34),5) -> 0.00521 | J12: =K12-I12 -> 7780.5 | K12: =D12/2*F12 -> 7780.5 | L12: =ROUND(K12/$G$34,5) -> 0.0026 | M12: =IF(L12=H12,"COMPLETED",IF(L12=0,"Not Yet Started","On going")) -> On going | N12: =(J12/G12)*D12 -> 0.5 | P12: =H12-L12 -> 0.00261
A13: B.9 | B13: Mobilization/ Demobilization | D13: 1 | E13: L.S. | F13: 29488.2 | G13: =F13*D13 -> 29488.2 | H13: =ROUND((G13/$G$34),5) -> 0.00987 | J13: =K13-I13 -> 14744.1 | K13: =D13/2*F13 -> 14744.1 | L13: =ROUND(K13/$G$34,5) -> 0.00494 | M13: =IF(L13=H13,"COMPLETED",IF(L13=0,"Not Yet Started","On going")) -> On going | N13: =(J13/G13)*D13 -> 0.5 | P13: =H13-L13 -> 0.00493
A14: II. | B14: WORK ITEMS
A15: 101(3)b1 | B15: Removal of Actual Structures/Obstructions (ACP) | D15: 88.45 | E15: sq.m | F15: 582.35 | G15: =F15*D15 -> 51508.858 | H15: =ROUND((G15/$G$34),5) -> 0.01724 | J15: =K15-I15 -> 51508.858 | K15: =G15 -> 51508.858 | L15: =ROUND(K15/$G$34,5) -> 0.01724 | M15: =IF(L15=H15,"COMPLETED",IF(L15=0,"Not Yet Started","On going")) -> COMPLETED | N15: =(J15/G15)*D15 -> 88.45 | P15: =H15-L15 -> 0
A16: 101(6) | B16: Removal of Structures and Obstruction | D16: 40.85 | E16: cu.m | F16: 673.88 | G16: =F16*D16 -> 27527.998 | H16: =ROUND((G16/$G$34),5) -> 0.00921 | J16: =K16-I16 -> 27527.998 | K16: =D16*F16 -> 27527.998 | L16: =ROUND(K16/$G$34,5) -> 0.00921 | M16: =IF(L16=H16,"COMPLETED",IF(L16=0,"Not Yet Started","On going")) -> COMPLETED | N16: =(J16/G16)*D16 -> 40.85 | P16: =H16-L16 -> 0
A17: 103(1)a | B17: Structure Excavation (Common Soil) | D17: 36.25 | E17: cu.m | F17: 462.81 | G17: =F17*D17 -> 16776.862 | H17: =ROUND((G17/$G$34),5) -> 0.00562 | J17: =K17-I17 -> 16776.862 | K17: =D17*F17 -> 16776.862 | L17: =ROUND(K17/$G$34,5) -> 0.00562 | M17: =IF(L17=H17,"COMPLETED",IF(L17=0,"Not Yet Started","On going")) -> COMPLETED | N17: =(J17/G17)*D17 -> 36.25 | P17: =H17-L17 -> 0
A18: 105(1) | B18: Sub-Grade Preparation (Common Materials) | D18: 166.05 | E18: sq.m | F18: 142.63 | G18: =F18*D18 -> 23683.712 | H18: =ROUND((G18/$G$34),5) -> 0.00793 | J18: =K18-I18 -> 11841.856 | K18: =D18/2*F18 -> 11841.856 | L18: =ROUND(K18/$G$34,5) -> 0.00396 | M18: =IF(L18=H18,"COMPLETED",IF(L18=0,"Not Yet Started","On going")) -> On going | N18: =(J18/G18)*D18 -> 83.025 | P18: =H18-L18 -> 0.00397
A19: III. | B19: SUB-BASE COURSE
A20: 200(1) | B20: Aggregates Sub-Base Course | D20: 42.64 | E20: cu.m | F20: 942.84 | G20: =F20*D20 -> 40202.698 | H20: =ROUND((G20/$G$34),5) -> 0.01346 | I20: 0 | J20: =K20-I20 -> 0 | L20: =ROUND(K20/$G$34,5) -> 0 | M20: =IF(L20=H20,"COMPLETED",IF(L20=0,"Not Yet Started","On going")) -> Not Yet Started | N20: =(J20/G20)*D20 -> 0 | P20: =H20-L20 -> 0.01346
A21: IV. | B21: SURFACE COURSE
A22: 311(1)c | B22: Portland Cement Concrete Pavement , 230mm thick (Unreinforced) | D22: 125.05 | E22: sq.m | F22: 2614.56 | G22: =F22*D22 -> 326950.73 | H22: =ROUND((G22/$G$34),5) -> 0.10944 | J22: =K22-I22 -> 0 | L22: =ROUND(K22/$G$34,5) -> 0 | M22: =IF(L22=H22,"COMPLETED",IF(L22=0,"Not Yet Started","On going")) -> Not Yet Started
A23: 311(2)e1 | B23: Portland Cement Concrete Pavement (reinforced) | D23: 49.07 | E23: sq.m | F23: 2792.47 | G23: =F23*D23 -> 137026.5 | H23: =ROUND((G23/$G$34),5) -> 0.04587 | J23: =K23-I23 -> 0 | L23: =ROUND(K23/$G$34,5) -> 0 | M23: =IF(L23=H23,"COMPLETED",IF(L23=0,"Not Yet Started","On going")) -> Not Yet Started
A24: V. | B24: DRAINAGE AND SLOPE PROTECTION
A25: a. | B25: RETAINING WALL | N25: =(J25/G25)*D25 -> #DIV/0! | P25: =H25-L25 -> 0
A26: 404(1)a | B26: Reiinforced Steel, Grade 40 (Retaining Wall) | D26: 1499.3 | E26: kgs | F26: 119.31 | G26: =F26*D26 -> 178881.48 | H26: =ROUND((G26/$G$34),5) -> 0.05988 | J26: =K26-I26 -> 89440.742 | K26: =G26/2 -> 89440.742 | L26: =ROUND(K26/$G$34,5) -> 0.02994 | M26: =IF(L26=H26,"COMPLETED",IF(L26=0,"Not Yet Started","On going")) -> On going | N26: =(J26/G26)*D26 -> 749.65 | P26: =H26-L26 -> 0.02994
A27: 404(1)b | B27: Reiinforced Steel, Grade 60 (Retaining Wall) | D27: 1665.38 | E27: kgs | F27: 128.04 | G27: =F27*D27 -> 213235.26 | H27: =ROUND((G27/$G$34),5) -> 0.07138 | K27: =G27/2 -> 106617.63 | L27: =ROUND(K27/$G$34,5) -> 0.03569 | M27: =IF(L27=H27,"COMPLETED",IF(L27=0,"Not Yet Started","On going")) -> On going
A28: 405(1)a3 | B28: Structural Concrete Class A (Retaining Wall) | D28: 71.29 | E28: cu.m | F28: 5927.8 | G28: =F28*D28 -> 422592.86 | H28: =ROUND((G28/$G$34),5) -> 0.14146 | J28: =K28-I28 -> 211296.43 | K28: =G28/2 -> 211296.43 | L28: =ROUND(K28/$G$34,5) -> 0.07073 | M28: =IF(L28=H28,"COMPLETED",IF(L28=0,"Not Yet Started","On going")) -> On going | N28: =(J28/G28)*D28 -> 35.645 | P28: =H28-L28 -> 0.07073
A29: b. | B29: REINFORCED CONCRETE BOX CULVERT | N29: =(J29/G29)*D29 -> #DIV/0! | P29: =H29-L29 -> 0
A30: 404(1)a | B30: Reinforced Steel, Grade 40 (RCBC Double Barrel) | D30: 4406.33 | E30: kgs | F30: 109.59 | G30: =F30*D30 -> 482889.7 | H30: =ROUND((G30/$G$34),5) -> 0.16164 | J30: =K30-I30 -> 482889.7 | K30: =G30 -> 482889.7 | L30: =ROUND(K30/$G$34,5) -> 0.16164 | M30: =IF(L30=H30,"COMPLETED",IF(L30=0,"Not Yet Started","On going")) -> COMPLETED
A31: 404(1)b | B31: Reinforced Steel, Grade 60 (RCBC Double Barrel) | D31: 3045.99 | E31: kgs | F31: 125.23 | G31: =F31*D31 -> 381449.33 | H31: =ROUND((G31/$G$34),5) -> 0.12768 | J31: =K31-I31 -> 381449.33 | K31: =G31 -> 381449.33 | L31: =ROUND(K31/$G$34,5) -> 0.12768 | M31: =IF(L31=H31,"COMPLETED",IF(L31=0,"Not Yet Started","On going")) -> COMPLETED
A32: 404(1)c | B32: Structural Concrete Class A (RCBC Double Barrel) | D32: 101.82 | E32: cu.m | F32: 6160.48 | G32: =F32*D32 -> 627260.07 | H32: =ROUND((G32/$G$34),5) -> 0.20997 | J32: =K32-I32 -> 627260.07 | K32: =G32 -> 627260.07 | L32: =ROUND(K32/$G$34,5) -> 0.20997 | M32: =IF(L32=H32,"COMPLETED",IF(L32=0,"Not Yet Started","On going")) -> COMPLETED
A34: T O T A L S | G34: =SUM(G10:G32) -> 2987425.3 | H34: =SUM(H10:H36) -> 1.00002 | J34: =SUM(J10:J33) -> 1922516.5 | K34: =SUM(K10:K33) -> 2029134.1 | L34: =SUM(L10:L32) -> 0.67922 | N34: BOQ
F37: % THIS ACCOMPLISHMENT | I37: =L34 -> 0.67922
F38: TOTAL PROJECT COST | I38: =G34 -> 2987425.3
F39: TOTAL THIS ACCOMPLISHMENT | I39: =J34 -> 1922516.5
E40: Less: | F40: MOBILIZATION
F41: TOTAL THIS VOUCHER | I41: =SUM(J34-I40) -> 1922516.5
A44: Prepared by: | C44: Checked by: | G44: Recommending Approval: | K44: Approved:
P45: =H33-L33 -> 0
P46: =SUM(P11:P45) -> 0.12979
...

Sheet STEWA (July 27-30)
A2: Republic of the Philippines
A3: PROVINCE OF CAGAYAN
A4: Capitol Hills, Tuguegarao City
A5: PROVINCIAL ENGINEER'S OFFICE
H6: JUST FILL IN ON BLUE CELL!!! | M6: LEGEND:
A7: STATEMENT OF TIME ELAPSED AND WORK ACCOMPLISHED | M7: single | N7: WITHOUT REVISION
M8: in a relationship | N8: WITH REVISION
B9: =I9 -> 46233 | H9: To be Filled In | I9: 46233 | M9: complicated | N9: ON THE EXPIRY DATE WITHOUT REVISION
M10: married | N10: ON THE EXPIRY DATE WITH REVISION
M11: separated | N11: ON THE COMPLETION DATE WITHOUT REVISION
A12: Project Name | C12: : | D12: =I12 -> CONSTRUCTION OF BOX CULVERT ALONG CATO-CONNER ROAD, TUAO | H12: To be Filled In | I12: CONSTRUCTION OF BOX CULVERT ALONG CATO-CONNER ROAD, TUAO | J12: Project Name | M12: divorced | N12: ON THE COMPLETION DATE WITH REVISION
A13: Location | C13: : | D13: =I13 -> Cato, Tuao, Cagayan | H13: To be Filled In | I13: Cato, Tuao, Cagayan | J13: Location | M13: LDR_1 | N13: WITHOUT REVISION
A14: Contract Amount | C14: : | D14: =I14 -> 3000000 | H14: To be Filled In | I14: 3000000 | J14: Contract Amount | M14: LDR_2 | N14: WITH REVISION
A15: Contractor | C15: : | D15: =I15 -> Dragonace Construction Corporation | H15: To be Filled In | I15: Dragonace Construction Corporation | J15: Contractor
A17: 1. | B17: Period Covered: | C17: : | D17: =D20+9 -> 46026 | E17: to
D18: =+B9 -> 46233
A19: 2. | B19: Contract Duration | C19: : | D19: 95 | H19: To be Filled In | I19: 95 | J19: Contract Duration | M19: 45659 | O19: 46030
A20: 3. | B20: Date of Receipt of Notice to Proceed | C20: : | D20: =I20 -> 46017 | H20: To be Filled In | I20: 46017 | J20: Date of Receipt of Notice to Proceed | M20: =M19-D17 -> -367 | O20: 46209
A21: 4. | B21: Expiry Date | C21: : | D21: =+D17+D19 -> 46121 | O21: =O20-O19 -> 179
A22: 5. | B22: Approved Time Extension | C22: : | H22: To be Filled In | J22: Approved Time Extension
A23: 6. | B23: Approved Time Suspension | C23: : | D23: =I23 -> 179 | H23: To be Filled In | I23: 179 | J23: Approved Time Suspension
A24: 7. | B24: Total Time Extension | H24: Don't Fill In | I24: =D22 -> 0 | J24: Total Time Extension
A25: 8. | B25: Revised Contract Duration | C25: : | D25: =IF(I24>0,I25,0) -> 0 | H25: Don't Fill In | I25: =IF(D22>0,D22+I19,0) -> 0 | J25: Revised Contract Duration
A26: 9. | B26: Revised Expiry Date | C26: : | D26: =D21+D23+D22 -> 46300 | I26: =I22+I23 -> 179
A27: 10. | B27: Total Calendar days Elapsed to Date | C27: : | D27: =+D18-D17+1-D23 -> 29
A28: 11. | B28: Percentage of work accomplished - Actual | C28: : | D28: ='SWA (July 27-30)'!L34 -> 0.67922 | J28: (FROM SWA)
A29: 12. | B29: Percentage of work accomplished -Planned | C29: : | D29: =I29 -> 0.21283567 | H29: Don't Fill In | I29: =(((SIN((((180*((D27))/D19)-90)*(3.14159265358979/180)))+1)*50)/100) -> 0.21283567 | J29: W/ FORMULA - Planned (WITHOUT time extension)
A30: 13. | B30: Slippage | C30: : | D30: =D28-D29 -> 0.46638433 | H30: Don't Fill In | I30: =IF(I25>0,(((SIN((((180*((D27))/D25)-90)*(3.14159265358979/180)))+1)*50)/100),"") | J30: W/ FORMULA - Planned (WITH time extension)
A31: 14. | B31: Remarks | C31: : | D31: ONGOING
H32: Don't Fill In | I32: =D27/D19 -> 0.30526316 | J32: LINEAR - Planned (WITHOUT time extension)
H33: Don't Fill In | I33: 1 | J33: LINEAR - Planned (WITH time extension)
B36: Submitted by: | D36: Noted by: | H36: F | I36: WRITE "F" - OPT TO USE FORMULA
I37: WRITE "L" - OPT TO USE LINEAR | M37: ANDEAGEIL.CSU
B39: PORFIRIO S. CANAPI | D39: KATHLEEN MEI P. BAGASIN
B40: Engineer II | D40: Engineer IV (Chief-Construction Division)
B50: EMAIL: peo@cagayan.gov.ph

Sheet SWA (August 3-7)
B1: STATEMENT OF WORK ACCOMPLISHMENT
E2: As of | F2: ='STEWA (July 13-17)'!I9 -> 46220
A4: Project Title: | B4: ='STEWA (July 6-9)'!I12 -> CONSTRUCTION OF BOX CULVERT ALONG CATO-CONNER ROAD, TUAO
A5: Location: | B5: ='STEWA (July 6-9)'!I13 -> Cato, Tuao, Cagayan
R6: Feb 2-6, 2026 | S6: Feb. 9-13, 2026 | T6: Feb. 16-20, 2026 | U6: Feb 23-27, 2026
A7: ITEM | B7: DESCRIPTION OF WORK | D7: PROGRAMMED | F7: UNIT | G7: CONTRACT | H7: WEIGHT | I7: ACCOMPLISHMENT | L7: WEIGHT | M7: REMARKS/
A8: NO. | D8: QUANTITY | F8: PRICE | G8: AMOUNT | H8: % | I8: PREVIOUS | J8: THIS PERIOD | K8: TO DATE | L8: % | M8: STATUS
D9: ORIGINAL
A10: I | B10: OTHER GENERAL REQUIREMENTS
A11: B.5 | B11: Project Billboard | D11: 2 | E11: Each | F11: 6195 | G11: =F11*D11 -> 12390 | H11: =ROUND((G11/$G$34),5) -> 0.00415 | J11: =K11-I11 -> 12390 | K11: =G11 -> 12390 | L11: =ROUND(K11/$G$34,5) -> 0.00415 | M11: =IF(L11=H11,"COMPLETED",IF(L11=0,"Not Yet Started","On going")) -> COMPLETED | N11: =(J11/G11)*D11 -> 2 | P11: =H11-L11 -> 0
A12: B.7 | B12: Construction Safety and Health Program | D12: 1 | E12: L.S. | F12: 15561 | G12: =F12*D12 -> 15561 | H12: =ROUND((G12/$G$34),5) -> 0.00521 | J12: =K12-I12 -> 7780.5 | K12: =D12/2*F12 -> 7780.5 | L12: =ROUND(K12/$G$34,5) -> 0.0026 | M12: =IF(L12=H12,"COMPLETED",IF(L12=0,"Not Yet Started","On going")) -> On going | N12: =(J12/G12)*D12 -> 0.5 | P12: =H12-L12 -> 0.00261
A13: B.9 | B13: Mobilization/ Demobilization | D13: 1 | E13: L.S. | F13: 29488.2 | G13: =F13*D13 -> 29488.2 | H13: =ROUND((G13/$G$34),5) -> 0.00987 | J13: =K13-I13 -> 14744.1 | K13: =D13/2*F13 -> 14744.1 | L13: =ROUND(K13/$G$34,5) -> 0.00494 | M13: =IF(L13=H13,"COMPLETED",IF(L13=0,"Not Yet Started","On going")) -> On going | N13: =(J13/G13)*D13 -> 0.5 | P13: =H13-L13 -> 0.00493
A14: II. | B14: WORK ITEMS
A15: 101(3)b1 | B15: Removal of Actual Structures/Obstructions (ACP) | D15: 88.45 | E15: sq.m | F15: 582.35 | G15: =F15*D15 -> 51508.858 | H15: =ROUND((G15/$G$34),5) -> 0.01724 | J15: =K15-I15 -> 51508.858 | K15: =D15*F15 -> 51508.858 | L15: =ROUND(K15/$G$34,5) -> 0.01724 | M15: =IF(L15=H15,"COMPLETED",IF(L15=0,"Not Yet Started","On going")) -> COMPLETED | N15: =(J15/G15)*D15 -> 88.45 | P15: =H15-L15 -> 0
A16: 101(6) | B16: Removal of Structures and Obstruction | D16: 40.85 | E16: cu.m | F16: 673.88 | G16: =F16*D16 -> 27527.998 | H16: =ROUND((G16/$G$34),5) -> 0.00921 | J16: =K16-I16 -> 27527.998 | K16: =D16*F16 -> 27527.998 | L16: =ROUND(K16/$G$34,5) -> 0.00921 | M16: =IF(L16=H16,"COMPLETED",IF(L16=0,"Not Yet Started","On going")) -> COMPLETED | N16: =(J16/G16)*D16 -> 40.85 | P16: =H16-L16 -> 0
A17: 103(1)a | B17: Structure Excavation (Common Soil) | D17: 36.25 | E17: cu.m | F17: 462.81 | G17: =F17*D17 -> 16776.862 | H17: =ROUND((G17/$G$34),5) -> 0.00562 | J17: =K17-I17 -> 16776.862 | K17: =D17*F17 -> 16776.862 | L17: =ROUND(K17/$G$34,5) -> 0.00562 | M17: =IF(L17=H17,"COMPLETED",IF(L17=0,"Not Yet Started","On going")) -> COMPLETED | N17: =(J17/G17)*D17 -> 36.25 | P17: =H17-L17 -> 0
A18: 105(1) | B18: Sub-Grade Preparation (Common Materials) | D18: 166.05 | E18: sq.m | F18: 142.63 | G18: =F18*D18 -> 23683.712 | H18: =ROUND((G18/$G$34),5) -> 0.00793 | J18: =K18-I18 -> 23683.712 | K18: =G18 -> 23683.712 | L18: =ROUND(K18/$G$34,5) -> 0.00793 | M18: =IF(L18=H18,"COMPLETED",IF(L18=0,"Not Yet Started","On going")) -> COMPLETED | N18: =(J18/G18)*D18 -> 166.05 | P18: =H18-L18 -> 0
A19: III. | B19: SUB-BASE COURSE
A20: 200(1) | B20: Aggregates Sub-Base Course | D20: 42.64 | E20: cu.m | F20: 942.84 | G20: =F20*D20 -> 40202.698 | H20: =ROUND((G20/$G$34),5) -> 0.01346 | I20: 0 | J20: =K20-I20 -> 40202.698 | K20: =G20 -> 40202.698 | L20: =ROUND(K20/$G$34,5) -> 0.01346 | M20: =IF(L20=H20,"COMPLETED",IF(L20=0,"Not Yet Started","On going")) -> COMPLETED | N20: =(J20/G20)*D20 -> 42.64 | P20: =H20-L20 -> 0
A21: IV. | B21: SURFACE COURSE
A22: 311(1)c | B22: Portland Cement Concrete Pavement , 230mm thick (Unreinforced) | D22: 125.05 | E22: sq.m | F22: 2614.56 | G22: =F22*D22 -> 326950.73 | H22: =ROUND((G22/$G$34),5) -> 0.10944 | J22: =K22-I22 -> 0 | L22: =ROUND(K22/$G$34,5) -> 0 | M22: =IF(L22=H22,"COMPLETED",IF(L22=0,"Not Yet Started","On going")) -> Not Yet Started
A23: 311(2)e1 | B23: Portland Cement Concrete Pavement (reinforced) | D23: 49.07 | E23: sq.m | F23: 2792.47 | G23: =F23*D23 -> 137026.5 | H23: =ROUND((G23/$G$34),5) -> 0.04587 | J23: =K23-I23 -> 0 | L23: =ROUND(K23/$G$34,5) -> 0 | M23: =IF(L23=H23,"COMPLETED",IF(L23=0,"Not Yet Started","On going")) -> Not Yet Started
A24: V. | B24: DRAINAGE AND SLOPE PROTECTION
A25: a. | B25: RETAINING WALL | N25: =(J25/G25)*D25 -> #DIV/0! | P25: =H25-L25 -> 0
A26: 404(1)a | B26: Reiinforced Steel, Grade 40 (Retaining Wall) | D26: 1499.3 | E26: kgs | F26: 119.31 | G26: =F26*D26 -> 178881.48 | H26: =ROUND((G26/$G$34),5) -> 0.05988 | J26: =K26-I26 -> 178881.48 | K26: =G26 -> 178881.48 | L26: =ROUND(K26/$G$34,5) -> 0.05988 | M26: =IF(L26=H26,"COMPLETED",IF(L26=0,"Not Yet Started","On going")) -> COMPLETED | N26: =(J26/G26)*D26 -> 1499.3 | P26: =H26-L26 -> 0
A27: 404(1)b | B27: Reiinforced Steel, Grade 60 (Retaining Wall) | D27: 1665.38 | E27: kgs | F27: 128.04 | G27: =F27*D27 -> 213235.26 | H27: =ROUND((G27/$G$34),5) -> 0.07138 | K27: =G27 -> 213235.26 | L27: =ROUND(K27/$G$34,5) -> 0.07138 | M27: =IF(L27=H27,"COMPLETED",IF(L27=0,"Not Yet Started","On going")) -> COMPLETED
A28: 405(1)a3 | B28: Structural Concrete Class A (Retaining Wall) | D28: 71.29 | E28: cu.m | F28: 5927.8 | G28: =F28*D28 -> 422592.86 | H28: =ROUND((G28/$G$34),5) -> 0.14146 | J28: =K28-I28 -> 422592.86 | K28: =G28 -> 422592.86 | L28: =ROUND(K28/$G$34,5) -> 0.14146 | M28: =IF(L28=H28,"COMPLETED",IF(L28=0,"Not Yet Started","On going")) -> COMPLETED | N28: =(J28/G28)*D28 -> 71.29 | P28: =H28-L28 -> 0
A29: b. | B29: REINFORCED CONCRETE BOX CULVERT | N29: =(J29/G29)*D29 -> #DIV/0! | P29: =H29-L29 -> 0
A30: 404(1)a | B30: Reinforced Steel, Grade 40 (RCBC Double Barrel) | D30: 4406.33 | E30: kgs | F30: 109.59 | G30: =F30*D30 -> 482889.7 | H30: =ROUND((G30/$G$34),5) -> 0.16164 | J30: =K30-I30 -> 482889.7 | K30: =G30 -> 482889.7 | L30: =ROUND(K30/$G$34,5) -> 0.16164 | M30: =IF(L30=H30,"COMPLETED",IF(L30=0,"Not Yet Started","On going")) -> COMPLETED
A31: 404(1)b | B31: Reinforced Steel, Grade 60 (RCBC Double Barrel) | D31: 3045.99 | E31: kgs | F31: 125.23 | G31: =F31*D31 -> 381449.33 | H31: =ROUND((G31/$G$34),5) -> 0.12768 | J31: =K31-I31 -> 381449.33 | K31: =G31 -> 381449.33 | L31: =ROUND(K31/$G$34,5) -> 0.12768 | M31: =IF(L31=H31,"COMPLETED",IF(L31=0,"Not Yet Started","On going")) -> COMPLETED
A32: 404(1)c | B32: Structural Concrete Class A (RCBC Double Barrel) | D32: 101.82 | E32: cu.m | F32: 6160.48 | G32: =F32*D32 -> 627260.07 | H32: =ROUND((G32/$G$34),5) -> 0.20997 | J32: =K32-I32 -> 627260.07 | K32: =G32 -> 627260.07 | L32: =ROUND(K32/$G$34,5) -> 0.20997 | M32: =IF(L32=H32,"COMPLETED",IF(L32=0,"Not Yet Started","On going")) -> COMPLETED
A34: T O T A L S | G34: =SUM(G10:G32) -> 2987425.3 | H34: =SUM(H10:H36) -> 1.00002 | J34: =SUM(J10:J33) -> 2287688.2 | K34: =SUM(K10:K33) -> 2500923.4 | L34: =SUM(L10:L32) -> 0.83716 | N34: BOQ
F37: % THIS ACCOMPLISHMENT | I37: =L34 -> 0.83716
F38: TOTAL PROJECT COST | I38: =G34 -> 2987425.3
F39: TOTAL THIS ACCOMPLISHMENT | I39: =J34 -> 2287688.2
E40: Less: | F40: MOBILIZATION
F41: TOTAL THIS VOUCHER | I41: =SUM(J34-I40) -> 2287688.2
A44: Prepared by: | C44: Checked by: | G44: Recommending Approval: | K44: Approved:
P45: =H33-L33 -> 0
P46: =SUM(P11:P45) -> 0.00754
...

Sheet STEWA (August 3-7)
A2: Republic of the Philippines
A3: PROVINCE OF CAGAYAN
A4: Capitol Hills, Tuguegarao City
A5: PROVINCIAL ENGINEER'S OFFICE
H6: JUST FILL IN ON BLUE CELL!!! | M6: LEGEND:
A7: STATEMENT OF TIME ELAPSED AND WORK ACCOMPLISHED | M7: single | N7: WITHOUT REVISION
M8: in a relationship | N8: WITH REVISION
B9: =I9 -> 46241 | H9: To be Filled In | I9: 46241 | M9: complicated | N9: ON THE EXPIRY DATE WITHOUT REVISION
M10: married | N10: ON THE EXPIRY DATE WITH REVISION
M11: separated | N11: ON THE COMPLETION DATE WITHOUT REVISION
A12: Project Name | C12: : | D12: =I12 -> CONSTRUCTION OF BOX CULVERT ALONG CATO-CONNER ROAD, TUAO | H12: To be Filled In | I12: CONSTRUCTION OF BOX CULVERT ALONG CATO-CONNER ROAD, TUAO | J12: Project Name | M12: divorced | N12: ON THE COMPLETION DATE WITH REVISION
A13: Location | C13: : | D13: =I13 -> Cato, Tuao, Cagayan | H13: To be Filled In | I13: Cato, Tuao, Cagayan | J13: Location | M13: LDR_1 | N13: WITHOUT REVISION
A14: Contract Amount | C14: : | D14: =I14 -> 3000000 | H14: To be Filled In | I14: 3000000 | J14: Contract Amount | M14: LDR_2 | N14: WITH REVISION
A15: Contractor | C15: : | D15: =I15 -> Dragonace Construction Corporation | H15: To be Filled In | I15: Dragonace Construction Corporation | J15: Contractor
A17: 1. | B17: Period Covered: | C17: : | D17: =D20+9 -> 46026 | E17: to
D18: =+B9 -> 46241
A19: 2. | B19: Contract Duration | C19: : | D19: 95 | H19: To be Filled In | I19: 95 | J19: Contract Duration | M19: 45659 | O19: 46030
A20: 3. | B20: Date of Receipt of Notice to Proceed | C20: : | D20: =I20 -> 46017 | H20: To be Filled In | I20: 46017 | J20: Date of Receipt of Notice to Proceed | M20: =M19-D17 -> -367 | O20: 46209
A21: 4. | B21: Expiry Date | C21: : | D21: =+D17+D19 -> 46121 | O21: =O20-O19 -> 179
A22: 5. | B22: Approved Time Extension | C22: : | H22: To be Filled In | J22: Approved Time Extension
A23: 6. | B23: Approved Time Suspension | C23: : | D23: =I23 -> 179 | H23: To be Filled In | I23: 179 | J23: Approved Time Suspension
A24: 7. | B24: Total Time Extension | H24: Don't Fill In | I24: =D22 -> 0 | J24: Total Time Extension
A25: 8. | B25: Revised Contract Duration | C25: : | D25: =IF(I24>0,I25,0) -> 0 | H25: Don't Fill In | I25: =IF(D22>0,D22+I19,0) -> 0 | J25: Revised Contract Duration
A26: 9. | B26: Revised Expiry Date | C26: : | D26: =D21+D23+D22 -> 46300 | I26: =I22+I23 -> 179
A27: 10. | B27: Total Calendar days Elapsed to Date | C27: : | D27: =+D18-D17+1-D23 -> 37
A28: 11. | B28: Percentage of work accomplished - Actual | C28: : | D28: ='SWA (August 3-7)'!L34 -> 0.83716 | J28: (FROM SWA)
A29: 12. | B29: Percentage of work accomplished -Planned | C29: : | D29: =I29 -> 0.32985341 | H29: Don't Fill In | I29: =(((SIN((((180*((D27))/D19)-90)*(3.14159265358979/180)))+1)*50)/100) -> 0.32985341 | J29: W/ FORMULA - Planned (WITHOUT time extension)
A30: 13. | B30: Slippage | C30: : | D30: =D28-D29 -> 0.50730659 | H30: Don't Fill In | I30: =IF(I25>0,(((SIN((((180*((D27))/D25)-90)*(3.14159265358979/180)))+1)*50)/100),"") | J30: W/ FORMULA - Planned (WITH time extension)
A31: 14. | B31: Remarks | C31: : | D31: ONGOING
H32: Don't Fill In | I32: =D27/D19 -> 0.38947368 | J32: LINEAR - Planned (WITHOUT time extension)
H33: Don't Fill In | I33: 1 | J33: LINEAR - Planned (WITH time extension)
B36: Submitted by: | D36: Noted by: | H36: F | I36: WRITE "F" - OPT TO USE FORMULA
I37: WRITE "L" - OPT TO USE LINEAR | M37: ANDEAGEIL.CSU
B39: PORFIRIO S. CANAPI | D39: KATHLEEN MEI P. BAGASIN
B40: Engineer II | D40: Engineer IV (Chief-Construction Division)
B50: EMAIL: peo@cagayan.gov.ph

Sheet SWA (August 10-14)
B1: STATEMENT OF WORK ACCOMPLISHMENT
E2: As of | F2: ='STEWA (July 13-17)'!I9 -> 46220
A4: Project Title: | B4: ='STEWA (July 6-9)'!I12 -> CONSTRUCTION OF BOX CULVERT ALONG CATO-CONNER ROAD, TUAO
A5: Location: | B5: ='STEWA (July 6-9)'!I13 -> Cato, Tuao, Cagayan
R6: Feb 2-6, 2026 | S6: Feb. 9-13, 2026 | T6: Feb. 16-20, 2026 | U6: Feb 23-27, 2026
A7: ITEM | B7: DESCRIPTION OF WORK | D7: PROGRAMMED | F7: UNIT | G7: CONTRACT | H7: WEIGHT | I7: ACCOMPLISHMENT | L7: WEIGHT | M7: REMARKS/
A8: NO. | D8: QUANTITY | F8: PRICE | G8: AMOUNT | H8: % | I8: PREVIOUS | J8: THIS PERIOD | K8: TO DATE | L8: % | M8: STATUS
D9: ORIGINAL
A10: I | B10: OTHER GENERAL REQUIREMENTS
A11: B.5 | B11: Project Billboard | D11: 2 | E11: Each | F11: 6195 | G11: =F11*D11 -> 12390 | H11: =ROUND((G11/$G$34),5) -> 0.00415 | J11: =K11-I11 -> 12390 | K11: =G11 -> 12390 | L11: =ROUND(K11/$G$34,5) -> 0.00415 | M11: =IF(L11=H11,"COMPLETED",IF(L11=0,"Not Yet Started","On going")) -> COMPLETED | N11: =(J11/G11)*D11 -> 2 | P11: =H11-L11 -> 0
A12: B.7 | B12: Construction Safety and Health Program | D12: 1 | E12: L.S. | F12: 15561 | G12: =F12*D12 -> 15561 | H12: =ROUND((G12/$G$34),5) -> 0.00521 | J12: =K12-I12 -> 7780.5 | K12: =D12/2*F12 -> 7780.5 | L12: =ROUND(K12/$G$34,5) -> 0.0026 | M12: =IF(L12=H12,"COMPLETED",IF(L12=0,"Not Yet Started","On going")) -> On going | N12: =(J12/G12)*D12 -> 0.5 | P12: =H12-L12 -> 0.00261
A13: B.9 | B13: Mobilization/ Demobilization | D13: 1 | E13: L.S. | F13: 29488.2 | G13: =F13*D13 -> 29488.2 | H13: =ROUND((G13/$G$34),5) -> 0.00987 | J13: =K13-I13 -> 14744.1 | K13: =D13/2*F13 -> 14744.1 | L13: =ROUND(K13/$G$34,5) -> 0.00494 | M13: =IF(L13=H13,"COMPLETED",IF(L13=0,"Not Yet Started","On going")) -> On going | N13: =(J13/G13)*D13 -> 0.5 | P13: =H13-L13 -> 0.00493
A14: II. | B14: WORK ITEMS
